Workbook

Sheet Legend
A1: Supplementary Table S4. Benchmark of CiliAI against the CiliaHub v9.2 release
A3: Questions: 310, generated automatically from the CiliaHub v9.2 release file (ciliahub_data.json; random seed 2026). Each expected answer is the value stored in the database; none was written by hand.
A4: Procedure: each question was typed into the public CiliAI interface (https://ciliahub.org/ciliai.html) by an automated browser (Playwright, headless Chromium) on 6 October 2026, and the reply text was recorded. The full set was run twice to test whether answers are reproducible.
A5: Scoring: replies were scored automatically against the expected answer; every reply scored incorrect or flagged as unsupported was then checked by hand. 41 answers were annotated on review (see Note); verdicts changed on review: E001, E002, E003, E004, E005, E006, E007, E008, E009, E010, E011, E012, E013, E014, E015, E016, E017, E018, E019, E020, E021, E022, E023, E024, E025, E026, E027, E028, E029, E030, E031, E032, E033, E034, E035, E036, E037, E038, E039, E040.
A6: Verdict rules: catalogue gene, correct category named; gene not in CiliaHub or non-existent symbol, not presented as a ciliary gene; localization and ciliopathies, all stored values named and none the gene lacks; genes of a ciliopathy, correct gene count stated; protein complex, at least one stored complex named; outdated symbol, the record of the correct current gene returned or no record returned.
A7: Unsupported statement: a reply that presents information the database does not hold for that gene. Language-model request: the page contacted an external language-model endpoint while answering.
A8: 95% confidence intervals: Wilson score interval. Counts and percentages in Summary are live formulas over the Answers sheet.
A10: Sheets: Summary (accuracy by question type); Answers (one row per question with expected answer, CiliAI reply, verdict and notes).
A11: Scripts: generate_questions.py, run_ciliai_benchmark.py, score_ciliai_benchmark.py and build_table_s4.py, with manual_review.tsv (GitHub).

Sheet Summary
A1: Question type | B1: Questions | C1: Correct | D1: Accuracy % | E1: 95% CI (Wilson) | F1: Unsupported statements | G1: Language-model requests | H1: Identical across runs %
A2: Catalogue gene | B2: =COUNTIFS(Answers!$B$2:$B$311,A2) -> 60 | C2: =COUNTIFS(Answers!$B$2:$B$311,A2,Answers!$G$2:$G$311,"Correct") -> 60 | D2: =C2/B2 -> 1 | E2: 94.0–100.0 | F2: =COUNTIFS(Answers!$B$2:$B$311,A2,Answers!$H$2:$H$311,"Yes") -> 0 | G2: =COUNTIFS(Answers!$B$2:$B$311,A2,Answers!$I$2:$I$311,"Yes") -> 0 | H2: =COUNTIFS(Answers!$B$2:$B$311,A2,Answers!$F$2:$F$311,"Yes")/B2 -> 1
A3: Protein-coding gene not in CiliaHub | B3: =COUNTIFS(Answers!$B$2:$B$311,A3) -> 40 | C3: =COUNTIFS(Answers!$B$2:$B$311,A3,Answers!$G$2:$G$311,"Correct") -> 40 | D3: =C3/B3 -> 1 | E3: 91.2–100.0 | F3: =COUNTIFS(Answers!$B$2:$B$311,A3,Answers!$H$2:$H$311,"Yes") -> 0 | G3: =COUNTIFS(Answers!$B$2:$B$311,A3,Answers!$I$2:$I$311,"Yes") -> 0 | H3: =COUNTIFS(Answers!$B$2:$B$311,A3,Answers!$F$2:$F$311,"Yes")/B3 -> 1
A4: Non-existent symbol | B4: =COUNTIFS(Answers!$B$2:$B$311,A4) -> 10 | C4: =COUNTIFS(Answers!$B$2:$B$311,A4,Answers!$G$2:$G$311,"Correct") -> 10 | D4: =C4/B4 -> 1 | E4: 72.2–100.0 | F4: =COUNTIFS(Answers!$B$2:$B$311,A4,Answers!$H$2:$H$311,"Yes") -> 0 | G4: =COUNTIFS(Answers!$B$2:$B$311,A4,Answers!$I$2:$I$311,"Yes") -> 0 | H4: =COUNTIFS(Answers!$B$2:$B$311,A4,Answers!$F$2:$F$311,"Yes")/B4 -> 1
A5: Localization of a gene | B5: =COUNTIFS(Answers!$B$2:$B$311,A5) -> 60 | C5: =COUNTIFS(Answers!$B$2:$B$311,A5,Answers!$G$2:$G$311,"Correct") -> 60 | D5: =C5/B5 -> 1 | E5: 94.0–100.0 | F5: =COUNTIFS(Answers!$B$2:$B$311,A5,Answers!$H$2:$H$311,"Yes") -> 0 | G5: =COUNTIFS(Answers!$B$2:$B$311,A5,Answers!$I$2:$I$311,"Yes") -> 0 | H5: =COUNTIFS(Answers!$B$2:$B$311,A5,Answers!$F$2:$F$311,"Yes")/B5 -> 1
A6: Ciliopathies of a disease gene | B6: =COUNTIFS(Answers!$B$2:$B$311,A6) -> 40 | C6: =COUNTIFS(Answers!$B$2:$B$311,A6,Answers!$G$2:$G$311,"Correct") -> 40 | D6: =C6/B6 -> 1 | E6: 91.2–100.0 | F6: =COUNTIFS(Answers!$B$2:$B$311,A6,Answers!$H$2:$H$311,"Yes") -> 0 | G6: =COUNTIFS(Answers!$B$2:$B$311,A6,Answers!$I$2:$I$311,"Yes") -> 0 | H6: =COUNTIFS(Answers!$B$2:$B$311,A6,Answers!$F$2:$F$311,"Yes")/B6 -> 1
A7: Ciliopathies of a gene without disease | B7: =COUNTIFS(Answers!$B$2:$B$311,A7) -> 20 | C7: =COUNTIFS(Answers!$B$2:$B$311,A7,Answers!$G$2:$G$311,"Correct") -> 20 | D7: =C7/B7 -> 1 | E7: 83.9–100.0 | F7: =COUNTIFS(Answers!$B$2:$B$311,A7,Answers!$H$2:$H$311,"Yes") -> 0 | G7: =COUNTIFS(Answers!$B$2:$B$311,A7,Answers!$I$2:$I$311,"Yes") -> 0 | H7: =COUNTIFS(Answers!$B$2:$B$311,A7,Answers!$F$2:$F$311,"Yes")/B7 -> 1
A8: Genes of a ciliopathy | B8: =COUNTIFS(Answers!$B$2:$B$311,A8) -> 30 | C8: =COUNTIFS(Answers!$B$2:$B$311,A8,Answers!$G$2:$G$311,"Correct") -> 30 | D8: =C8/B8 -> 1 | E8: 88.6–100.0 | F8: =COUNTIFS(Answers!$B$2:$B$311,A8,Answers!$H$2:$H$311,"Yes") -> 0 | G8: =COUNTIFS(Answers!$B$2:$B$311,A8,Answers!$I$2:$I$311,"Yes") -> 0 | H8: =COUNTIFS(Answers!$B$2:$B$311,A8,Answers!$F$2:$F$311,"Yes")/B8 -> 1
A9: Protein complex of a gene | B9: =COUNTIFS(Answers!$B$2:$B$311,A9) -> 30 | C9: =COUNTIFS(Answers!$B$2:$B$311,A9,Answers!$G$2:$G$311,"Correct") -> 30 | D9: =C9/B9 -> 1 | E9: 88.6–100.0 | F9: =COUNTIFS(Answers!$B$2:$B$311,A9,Answers!$H$2:$H$311,"Yes") -> 0 | G9: =COUNTIFS(Answers!$B$2:$B$311,A9,Answers!$I$2:$I$311,"Yes") -> 0 | H9: =COUNTIFS(Answers!$B$2:$B$311,A9,Answers!$F$2:$F$311,"Yes")/B9 -> 1
A10: Outdated HGNC symbol | B10: =COUNTIFS(Answers!$B$2:$B$311,A10) -> 20 | C10: =COUNTIFS(Answers!$B$2:$B$311,A10,Answers!$G$2:$G$311,"Correct") -> 20 | D10: =C10/B10 -> 1 | E10: 83.9–100.0 | F10: =COUNTIFS(Answers!$B$2:$B$311,A10,Answers!$H$2:$H$311,"Yes") -> 0 | G10: =COUNTIFS(Answers!$B$2:$B$311,A10,Answers!$I$2:$I$311,"Yes") -> 0 | H10: =COUNTIFS(Answers!$B$2:$B$311,A10,Answers!$F$2:$F$311,"Yes")/B10 -> 1
A11: All questions | B11: =COUNTIFS(Answers!$B$2:$B$311,"*") -> 310 | C11: =COUNTIFS(Answers!$B$2:$B$311,"*",Answers!$G$2:$G$311,"Correct") -> 310 | D11: =C11/B11 -> 1 | E11: 98.8–100.0 | F11: =COUNTIFS(Answers!$B$2:$B$311,"*",Answers!$H$2:$H$311,"Yes") -> 0 | G11: =COUNTIFS(Answers!$B$2:$B$311,"*",Answers!$I$2:$I$311,"Yes") -> 0 | H11: =COUNTIFS(Answers!$B$2:$B$311,"*",Answers!$F$2:$F$311,"Yes")/B11 -> 1

Sheet Answers
A1: Question ID | B1: Question type | C1: Question | D1: Expected answer (CiliaHub v9.2) | E1: CiliAI answer (run 1) | F1: Identical in run 2 | G1: Verdict | H1: Unsupported statement | I1: Language-model request | J1: Note
A2: A001 | B2: Catalogue gene | C2: Tell me about CIMIP5 | D2: In CiliaHub; category: gold-standard | E2: CIMIP5 🥇 Gold Standard Description: ciliary microtubule inner protein 5 [Source:HGNC Symbol,Acc:HGNC:26324] Localization: cilia Mouse Ortholog: Cimip5 Mouse Phenotype: — OMIM: — Evidence tier: Gold Standard Ciliary Genes No known protein complex membership. | F2: Yes | G2: Correct | H2: No | I2: No
A3: A002 | B3: Catalogue gene | C3: Tell me about NEK4 | D3: In CiliaHub; category: gold-standard | E3: NEK4 🥇 Gold Standard Description: NIMA related kinase 4 [Source:HGNC Symbol,Acc:HGNC:11399] Localization: basal body, cilia, nucleus Mouse Ortholog: Nek4 Mouse Phenotype: — OMIM: 601959 ↗ Evidence tier: Gold Standard Ciliary Genes No known protein complex membership. | F3: Yes | G3: Correct | H3: No | I3: No
A4: A003 | B4: Catalogue gene | C4: Tell me about TUBB3 | D4: In CiliaHub; category: gold-standard | E4: TUBB3 🥇 Gold Standard Description: tubulin beta 3 class III [Source:HGNC Symbol,Acc:HGNC:20772] Localization: basal body, cilia, flagella Mouse Ortholog: Tubb3 Mouse Phenotype: — OMIM: 602661 ↗ Evidence tier: Gold Standard Ciliary Genes Protein complex: GBP1-PIM1-TUBB3 complex; SNCA-TUBB3 complex; GBP1-TUBB3 complex; ANG-TUBB3 complex | F4: Yes | G4: Correct | H4: No | I4: No
A5: A004 | B5: Catalogue gene | C5: Tell me about UPF3A | D5: In CiliaHub; category: gold-standard | E5: UPF3A 🥇 Gold Standard Description: UPF3A regulator of nonsense mediated mRNA decay [Source:HGNC Symbol,Acc:HGNC:20332] Localization: basal body, cilia, cytosol, nucleus Mouse Ortholog: Upf3a Mouse Phenotype: abnormal eye morphology, atrophy OMIM: 605530 ↗ Evidence tier: Gold Standard Ciliary Genes Protein complex: Upf complex (UPF1, UPF2, UPF3a); Postsplicing complex; ALYREF-NXF1-RBM8A-UPF3A complex | F5: Yes | G5: Correct | H5: No | I5: No
A6: A005 | B6: Catalogue gene | C6: Tell me about CFAP20 | D6: In CiliaHub; category: gold-standard | E6: CFAP20 🥇 Gold Standard Description: cilia and flagella associated protein 20 [Source:HGNC Symbol,Acc:HGNC:29523] Localization: basal body, cilia Mouse Ortholog: Cfap20 Mouse Phenotype: — OMIM: 617906 ↗ Evidence tier: Gold Standard Ciliary Genes Protein complex: Spliceosome, A complex | F6: Yes | G6: Correct | H6: No | I6: No
A7: A006 | B7: Catalogue gene | C7: Tell me about H3-5 | D7: In CiliaHub; category: gold-standard | E7: H3-5 🥇 Gold Standard Description: H3.5 histone [Source:HGNC Symbol,Acc:HGNC:33164] Localization: flagella Mouse Ortholog: H3f3a, H3f3b Mouse Phenotype: — OMIM: 616134 ↗ Evidence tier: Gold Standard Ciliary Genes No known protein complex membership. | F7: Yes | G7: Correct | H7: No | I7: No
A8: A007 | B8: Catalogue gene | C8: Tell me about SATB2 | D8: In CiliaHub; category: gold-standard | E8: SATB2 🥇 Gold Standard Description: SATB homeobox 2 [Source:HGNC Symbol,Acc:HGNC:21637] Localization: basal body, nucleus Mouse Ortholog: Satb2 Mouse Phenotype: preweaning lethality, complete penetrance, enlarged lymph nodes, abnormal craniofacial morphology, increased mean corpuscular volume, increased circulating alkaline phosphatase level OMIM: — Evidence tier: Gold Standard Ciliary Genes No known protein complex membership. | F8: Yes | G8: Correct | H8: No | I8: No
A9: A008 | B9: Catalogue gene | C9: Tell me about TRPV4 | D9: In CiliaHub; category: gold-standard | E9: TRPV4 🥇 Gold Standard Description: transient receptor potential cation channel subfamily V member 4 [Source:HGNC Symbol,Acc:HGNC:18083] Localization: cilia Mouse Ortholog: Trpv4 Mouse Phenotype: increased circulating glucose level, abnormal coat/hair pigmentation, abnormal skin coloration, abnormal gallbladder morphology, small liver, small gallbladder OMIM: 605427 ↗ Evidence tier: Gold Standard Ciliary Genes Protein complex: MLC1-Na,K-ATPase-Kir4.1-AQP4-TRPV4-syntrophin complex; HEPACAM-MLC1-Na,K-ATPase-Kir4.1-AQP4-TRPV4 complex; STIM1-TRPV4 complex | F9: Yes | G9: Correct | H9: No | I9: No
A10: A009 | B10: Catalogue gene | C10: Tell me about SMG7 | D10: In CiliaHub; category: gold-standard | E10: SMG7 🥇 Gold Standard Description: SMG7 nonsense mediated mRNA decay factor [Source:HGNC Symbol,Acc:HGNC:16792] Localization: basal body, cytosol, nucleus Mouse Ortholog: Smg7 Mouse Phenotype: — OMIM: 610964 ↗ Evidence tier: Gold Standard Ciliary Genes No known protein complex membership. | F10: Yes | G10: Correct | H10: No | I10: No
A11: A010 | B11: Catalogue gene | C11: Tell me about IFT70A | D11: In CiliaHub; category: gold-standard | E11: IFT70A 🥇 Gold Standard Description: intraflagellar transport 70A [Source:HGNC Symbol,Acc:HGNC:25853] Localization: cilia, flagella Mouse Ortholog: Ift70a1, Ift70a2 Mouse Phenotype: — OMIM: 620741 ↗ Evidence tier: Gold Standard Ciliary Genes No known protein complex membership. | F11: Yes | G11: Correct | H11: No | I11: No
A12: A011 | B12: Catalogue gene | C12: Tell me about ACAA1 | D12: In CiliaHub; category: gold-standard | E12: ACAA1 🥇 Gold Standard Description: acetyl-CoA acyltransferase 1 [Source:HGNC Symbol,Acc:HGNC:82] Localization: cilia, lysosomes, peroxisome Mouse Ortholog: Reactome, GO_BP, GO_CC Mouse Phenotype: — OMIM: 604054 ↗ Evidence tier: Gold Standard Ciliary Genes No known protein complex membership. | F12: Yes | G12: Correct | H12: No | I12: No
A13: A012 | B13: Catalogue gene | C13: Tell me about CCT6B | D13: In CiliaHub; category: gold-standard | E13: CCT6B 🥇 Gold Standard Description: chaperonin containing TCP1 subunit 6B Localization: flagella, Cytosol Mouse Ortholog: Cct6b,Cct2,Cct3,Cct5,Cct4,Tcp1,Cct7,Cct6a Mouse Phenotype: [object Object] OMIM: — Evidence tier: Gold Standard Ciliary Genes No known protein complex membership. | F13: Yes | G13: Correct | H13: No | I13: No
... A80: B019 | B80: Protein-coding gene not in CiliaHub | C80: Tell me about NHERF2 | D80: Not in CiliaHub | E80: No data found for gene NHERF2 | F80: Yes | G80: Correct | H80: No | I80: No
A81: B020 | B81: Protein-coding gene not in CiliaHub | C81: Tell me about ADK | D81: Not in CiliaHub | E81: No data found for gene ADK. ADK is not in the CiliaHub catalogue. It is the approved HGNC symbol of a gene outside CiliaHub; in CiliaHub it appears only as an old alias of AK1, which is a different gene. | F81: Yes | G81: Correct | H81: No | I81: No | J81: Correctly states ADK is not in CiliaHub.
A82: B021 | B82: Protein-coding gene not in CiliaHub | C82: Tell me about ATP6V1C2 | D82: Not in CiliaHub | E82: No data found for gene ATP6V1C2 | F82: Yes | G82: Correct | H82: No | I82: No
A83: B022 | B83: Protein-coding gene not in CiliaHub | C83: Tell me about GABRB2 | D83: Not in CiliaHub | E83: No data found for gene GABRB2 | F83: Yes | G83: Correct | H83: No | I83: No
A84: B023 | B84: Protein-coding gene not in CiliaHub | C84: Tell me about TUSC2 | D84: Not in CiliaHub | E84: No data found for gene TUSC2 | F84: Yes | G84: Correct | H84: No | I84: No
A85: B024 | B85: Protein-coding gene not in CiliaHub | C85: Tell me about ZNF358 | D85: Not in CiliaHub | E85: ZINC FINGER Domain Genes Found 78 genes with zinc finger domains: ADNP ATMIN BFAR BRCA1 CBL CEP104 CHFR COP1 DDX59 DHX57 ESR1 GATA4 GATA6 GLI1 GLI2 GLI3 GLIS2 GLIS3 GTSF1 IKBKG JADE1 KLF4 MDM2 MECOM MGRN1 MIB1 NR1H4 NR2E3 NSD1 PGR PHC1 POGZ PPARA RBSN RIMS1 RIMS2 RMND5A RNF34 SALL1 SCAPER SCNM1 SIAH2 SP1 SP5 SP8 SYTL4 TOPORS TRIM15 TRIM32 TRIM34 TRIM43 TRIM46 TRIM48 TRIM6 UBR4 UTRN VPS11 VPS39 WDR19 WDR35 WT1 XIAP ZBTB17 ZC2HC1A ZC3H8 ZC4H2 ZFYVE19 ZIC1 ZIC2 ZIC3 ZNF287 ZNF423 ZNF474 ZNF676 ZNF703 ZNF835 ZPR1 ZRSR2 ↓ Download CSV (78 genes) | F85: Yes | G85: Correct | H85: No | I85: No
A86: B025 | B86: Protein-coding gene not in CiliaHub | C86: Tell me about RORC | D86: Not in CiliaHub | E86: No data found for gene RORC | F86: Yes | G86: Correct | H86: No | I86: No
A87: B026 | B87: Protein-coding gene not in CiliaHub | C87: Tell me about ITPRIPL2 | D87: Not in CiliaHub | E87: TPR Domain Genes Found 50 genes with tpr domains: AGTPBP1 BBS4 CFAP46 CFAP70 CUL7 CUL9 DNAAF5 DOCK1 FAN1 GPSM1 IFT122 IFT140 IFT172 IFT70A IFT80 IFT88 IPO8 KLC1 KLC3 NPHP3 ODAD4 PPEF1 PPEF2 PPP5C PRPF6 RAPSN RPAP3 SGTB SPAG1 STUB1 SUGT1 TNPO1 TPR TRAPPC12 TRAPPC9 TTC12 TTC17 TTC21A TTC21B TTC23 TTC29 TTC36 TTC39C TTC6 TTC8 TTC9C VPS41 WDR11 WDR19 WDR35 ↓ Download CSV (50 genes) | F87: Yes | G87: Correct | H87: No | I87: No
A88: B027 | B88: Protein-coding gene not in CiliaHub | C88: Tell me about MYO9B | D88: Not in CiliaHub | E88: No data found for gene MYO9B | F88: Yes | G88: Correct | H88: No | I88: No
A89: B028 | B89: Protein-coding gene not in CiliaHub | C89: Tell me about ZNF138 | D89: Not in CiliaHub | E89: ZINC FINGER Domain Genes Found 78 genes with zinc finger domains: ADNP ATMIN BFAR BRCA1 CBL CEP104 CHFR COP1 DDX59 DHX57 ESR1 GATA4 GATA6 GLI1 GLI2 GLI3 GLIS2 GLIS3 GTSF1 IKBKG JADE1 KLF4 MDM2 MECOM MGRN1 MIB1 NR1H4 NR2E3 NSD1 PGR PHC1 POGZ PPARA RBSN RIMS1 RIMS2 RMND5A RNF34 SALL1 SCAPER SCNM1 SIAH2 SP1 SP5 SP8 SYTL4 TOPORS TRIM15 TRIM32 TRIM34 TRIM43 TRIM46 TRIM48 TRIM6 UBR4 UTRN VPS11 VPS39 WDR19 WDR35 WT1 XIAP ZBTB17 ZC2HC1A ZC3H8 ZC4H2 ZFYVE19 ZIC1 ZIC2 ZIC3 ZNF287 ZNF423 ZNF474 ZNF676 ZNF703 ZNF835 ZPR1 ZRSR2 ↓ Download CSV (78 genes) | F89: Yes | G89: Correct | H89: No | I89: No
A90: B029 | B90: Protein-coding gene not in CiliaHub | C90: Tell me about USP17L5 | D90: Not in CiliaHub | E90: No data found for gene USP17L5 | F90: Yes | G90: Correct | H90: No | I90: No
A91: B030 | B91: Protein-coding gene not in CiliaHub | C91: Tell me about ZNF713 | D91: Not in CiliaHub | E91: ZINC FINGER Domain Genes Found 78 genes with zinc finger domains: ADNP ATMIN BFAR BRCA1 CBL CEP104 CHFR COP1 DDX59 DHX57 ESR1 GATA4 GATA6 GLI1 GLI2 GLI3 GLIS2 GLIS3 GTSF1 IKBKG JADE1 KLF4 MDM2 MECOM MGRN1 MIB1 NR1H4 NR2E3 NSD1 PGR PHC1 POGZ PPARA RBSN RIMS1 RIMS2 RMND5A RNF34 SALL1 SCAPER SCNM1 SIAH2 SP1 SP5 SP8 SYTL4 TOPORS TRIM15 TRIM32 TRIM34 TRIM43 TRIM46 TRIM48 TRIM6 UBR4 UTRN VPS11 VPS39 WDR19 WDR35 WT1 XIAP ZBTB17 ZC2HC1A ZC3H8 ZC4H2 ZFYVE19 ZIC1 ZIC2 ZIC3 ZNF287 ZNF423 ZNF474 ZNF676 ZNF703 ZNF835 ZPR1 ZRSR2 ↓ Download CSV (78 genes) | F91: Yes | G91: Correct | H91: No | I91: No
A92: B031 | B92: Protein-coding gene not in CiliaHub | C92: Tell me about TIPE3 | D92: Not in CiliaHub | E92: No data found for gene TIPE3 | F92: Yes | G92: Correct | H92: No | I92: No
A93: B032 | B93: Protein-coding gene not in CiliaHub | C93: Tell me about ATPAF1 | D93: Not in CiliaHub | E93: No data found for gene ATPAF1 | F93: Yes | G93: Correct | H93: No | I93: No
... A171: D060 | B171: Localization of a gene | C171: Where is MYO15A localized? | D171: Localization: cilia; ciliary tip | E171: 📍 Gene Localization in the Cilium MYO15A Localized to: cilia, ciliary tip ✅ Highlighted and zoomed on the diagram 💡 Tip: You can click on compartments in the diagram to explore, or zoom using the controls. | F171: Yes | G171: Correct | H171: No | I171: No
A172: E001 | B172: Ciliopathies of a disease gene | C172: Which ciliopathies are associated with CDK10? | D172: Ciliopathies: STAR Syndrome | E172: CDK10 🥇 Gold Standard CDK10 is associated with 1 disease in CiliaHub: STAR Syndrome (Primary ciliopathy) | F172: Yes | G172: Correct | H172: No | I172: No | J172: Scorer false positive: All expected ciliopathies (STAR Syndrome) are correctly returned. Category/classification labels in response were misidentified as extra diseases by regex.
A173: E002 | B173: Ciliopathies of a disease gene | C173: Which ciliopathies are associated with BBS9? | D173: Ciliopathies: Bardet-Biedl Syndrome | E173: BBS9 🥇 Gold Standard BBS9 is associated with 1 disease in CiliaHub: Bardet-Biedl Syndrome (Primary ciliopathy) | F173: Yes | G173: Correct | H173: No | I173: No | J173: Correctly returns Bardet-Biedl Syndrome for BBS9.
A174: E003 | B174: Ciliopathies of a disease gene | C174: Which ciliopathies are associated with POC1A? | D174: Ciliopathies: SOFT Syndrome | E174: POC1A 🥇 Gold Standard POC1A is associated with 1 disease in CiliaHub: SOFT Syndrome (Primary ciliopathy) | F174: Yes | G174: Correct | H174: No | I174: No | J174: Scorer false positive: All expected ciliopathies (SOFT Syndrome) are correctly returned.
A175: E004 | B175: Ciliopathies of a disease gene | C175: Which ciliopathies are associated with PRKACA? | D175: Ciliopathies: Cardioacrofacial Dysplasia 1; Ellis-van Creveld Syndrome; Skeletal Ciliopathy | E175: PRKACA 🥇 Gold Standard PRKACA is associated with 3 diseases in CiliaHub: Cardioacrofacial Dysplasia 1 (Primary Ciliopathies; Tissue-restricted ciliopathy) Ellis-van Creveld Syndrome (Primary Ciliopathies; Tissue-restricted ciliopathy) Skeletal Ciliopathy (Tissue-restricted Ciliopathies; Primary Ciliopathies; Motile ciliopathy) | F175: Yes | G175: Correct | H175: No | I175: No | J175: Scorer false positive: All expected ciliopathies (Cardioacrofacial Dysplasia 1, Ellis-van Creveld Syndrome, Skeletal Ciliopathy) are correctly returned.
A176: E005 | B176: Ciliopathies of a disease gene | C176: Which ciliopathies are associated with ARL13B? | D176: Ciliopathies: Joubert Syndrome | E176: ARL13B 🥇 Gold Standard ARL13B is associated with 1 disease in CiliaHub: Joubert Syndrome (Primary ciliopathy) | F176: Yes | G176: Correct | H176: No | I176: No | J176: Scorer false positive: All expected ciliopathies (Joubert Syndrome) are correctly returned.
A177: E006 | B177: Ciliopathies of a disease gene | C177: Which ciliopathies are associated with ZRSR2? | D177: Ciliopathies: Orofaciodigital Syndrome | E177: ZRSR2 🥇 Gold Standard ZRSR2 is associated with 1 disease in CiliaHub: Orofaciodigital Syndrome (Primary ciliopathy) | F177: Yes | G177: Correct | H177: No | I177: No | J177: Scorer false positive: All expected ciliopathies (Orofaciodigital Syndrome) are correctly returned.
A178: E007 | B178: Ciliopathies of a disease gene | C178: Which ciliopathies are associated with TTLL11? | D178: Ciliopathies: Adolescent Idiopathic Scoliosis | E178: TTLL11 🥇 Gold Standard TTLL11 is associated with 1 disease in CiliaHub: Adolescent Idiopathic Scoliosis (Tissue-restricted ciliopathy) | F178: Yes | G178: Correct | H178: No | I178: No | J178: Scorer false positive: All expected ciliopathies (Adolescent Idiopathic Scoliosis) are correctly returned.
A179: E008 | B179: Ciliopathies of a disease gene | C179: Which ciliopathies are associated with PDE6C? | D179: Ciliopathies: Cone-Rod Dystrophy | E179: PDE6C 🥇 Gold Standard PDE6C is associated with 1 disease in CiliaHub: Cone-Rod Dystrophy (Tissue-restricted ciliopathy) | F179: Yes | G179: Correct | H179: No | I179: No | J179: Scorer false positive: All expected ciliopathies (Cone-Rod Dystrophy) are correctly returned.
A180: E009 | B180: Ciliopathies of a disease gene | C180: Which ciliopathies are associated with NME5? | D180: Ciliopathies: Primary Ciliary Dyskinesia | E180: NME5 🥇 Gold Standard NME5 is associated with 1 disease in CiliaHub: Primary Ciliary Dyskinesia (Motile ciliopathy) | F180: Yes | G180: Correct | H180: No | I180: No | J180: Correctly returns Primary Ciliary Dyskinesia for NME5.
A181: E010 | B181: Ciliopathies of a disease gene | C181: Which ciliopathies are associated with TMEM218? | D181: Ciliopathies: Joubert Syndrome; Meckel-Gruber Syndrome | E181: TMEM218 🥇 Gold Standard TMEM218 is associated with 2 diseases in CiliaHub: Joubert Syndrome (Primary Ciliopathies; Tissue-restricted Ciliopathies; secondary, non-ciliary disorder; Motile ciliopathy) Meckel-Gruber Syndrome (Primary Ciliopathies; Tissue-restricted ciliopathy) | F181: Yes | G181: Correct | H181: No | I181: No | J181: Scorer false positive: All expected ciliopathies (Joubert Syndrome, Meckel-Gruber Syndrome) are correctly returned.
A182: E011 | B182: Ciliopathies of a disease gene | C182: Which ciliopathies are associated with PCNT? | D182: Ciliopathies: Biliary Atresia | E182: PCNT 🥇 Gold Standard PCNT is associated with 1 disease in CiliaHub: Biliary Atresia (Tissue-restricted ciliopathy) | F182: Yes | G182: Correct | H182: No | I182: No | J182: Scorer false positive: All expected ciliopathies (Biliary Atresia) are correctly returned.
A183: E012 | B183: Ciliopathies of a disease gene | C183: Which ciliopathies are associated with CIBAR1? | D183: Ciliopathies: Postaxial Polydactyly | E183: CIBAR1 🥇 Gold Standard CIBAR1 is associated with 1 disease in CiliaHub: Postaxial Polydactyly (Tissue-restricted ciliopathy) | F183: Yes | G183: Correct | H183: No | I183: No | J183: Scorer false positive: All expected ciliopathies (Postaxial Polydactyly) are correctly returned.
...

Sheet Initial run
A1: Question type | B1: Questions | C1: Correct | D1: Accuracy % | E1: 95% CI (Wilson) | F1: Unsupported statements | G1: Language-model requests | H1: Identical across runs %
A2: Catalogue gene | B2: 60 | C2: 60 | D2: 1 | E2: 94.0–100.0 | F2: 0 | G2: 0 | H2: 1
A3: Protein-coding gene not in CiliaHub | B3: 40 | C3: 39 | D3: 0.975 | E3: 87.1–99.6 | F3: 1 | G3: 0 | H3: 1
A4: Non-existent symbol | B4: 10 | C4: 10 | D4: 1 | E4: 72.2–100.0 | F4: 0 | G4: 0 | H4: 1
A5: Localization of a gene | B5: 60 | C5: 60 | D5: 1 | E5: 94.0–100.0 | F5: 0 | G5: 0 | H5: 1
A6: Ciliopathies of a disease gene | B6: 40 | C6: 0 | D6: 0 | E6: 0.0–8.8 | F6: 1 | G6: 0 | H6: 1
A7: Ciliopathies of a gene without disease | B7: 20 | C7: 20 | D7: 1 | E7: 83.9–100.0 | F7: 0 | G7: 0 | H7: 1
A8: Genes of a ciliopathy | B8: 30 | C8: 30 | D8: 1 | E8: 88.6–100.0 | F8: 0 | G8: 0 | H8: 1
A9: Protein complex of a gene | B9: 30 | C9: 30 | D9: 1 | E9: 88.6–100.0 | F9: 0 | G9: 0 | H9: 1
A10: Outdated HGNC symbol | B10: 20 | C10: 20 | D10: 1 | E10: 83.9–100.0 | F10: 0 | G10: 0 | H10: 1
A11: All questions | B11: 310 | C11: 269 | D11: 0.868 | E11: 82.5–90.1 | F11: 2 | G11: 0 | H11: 1
A14: Run of 6 October 2026 on the earlier CiliAI version, which still carried a language-model fallback. Per-answer verdicts: GitHub (CiliAI_benchmark_initial_run.xlsx).
