Workbook

Sheet Legend
A1: Supplementary Table S3. Validation of CiliaHub against independent clinical gene panels (PanelApp Australia)
A3: CiliaHub release: v9.2 (frozen 2026-10-03); 2,785 genes (2,179 gold-standard, 606 cilia-associated).
A4: Panels: PanelApp Australia (https://panelapp-aus.org), downloaded 26 September 2026 as TSV: Ciliopathies (panel 84, v2.21), Ciliary Dyskinesia (panel 82, v2.0) and, as a non-ciliary control, Dilated Cardiomyopathy (panel 95, v2.12).
A5: Only gene entities were analysed; the two copy-number region entities on the Ciliopathies panel (NPHP1 deletion, 17q12 deletion) were excluded, as their key genes (NPHP1, HNF1B) are listed as gene entities.
A6: PanelApp rating: Green = diagnostic-grade evidence (primary analysis); Amber = moderate evidence; Red = insufficient evidence.
A8: Gene matching, in order of priority: (1) panel GRCh38 Ensembl ID matched to a CiliaHub Ensembl ID; (2) Ensembl ID mapped to its current HGNC symbol, then matched to CiliaHub; (3) exact current symbol; (4) HGNC previous symbol, CiliaHub synonym, then HGNC alias, used only when unique and not itself a current HGNC symbol of another gene.
A9: Ciliopathy module: CiliaHub genes linked to at least one ciliopathy (primary, motile or tissue-restricted); genes linked only to secondary disorders are excluded.
A10: Fold enrichment = (fraction of panel genes captured) / (fraction of the 19,214 protein-coding genes in CiliaHub or in the module).
A12: Sheets:
A13: Summary: recall, category split, ciliopathy-module recall, fold enrichment and Fisher P values, by panel and rating.
A14: Ciliopathies, Ciliary Dyskinesia, Dilated Cardiomyopathy: one row per panel gene, with the panel annotation and the matched CiliaHub record.

Sheet Summary
A1: Panel | B1: Role | C1: PanelApp rating | D1: Genes | E1: In CiliaHub | F1: % in CiliaHub | G1: Gold-standard | H1: Cilia-associated | I1: In ciliopathy module | J1: % in ciliopathy module | K1: Fold enrichment, CiliaHub | L1: Fisher P, CiliaHub (one-sided) | M1: Fold enrichment, module | N1: Fisher P, module (one-sided)
A2: Ciliopathies (panel 84, v2.21) | B2: Ciliary (test) | C2: Green | D2: =COUNTIFS(Ciliopathies!$B$2:$B$163,"Green") -> 131 | E2: =COUNTIFS(Ciliopathies!$B$2:$B$163,"Green",Ciliopathies!$H$2:$H$163,"Yes") -> 131 | F2: =IF(D2=0,"",E2/D2) -> 1 | G2: =COUNTIFS(Ciliopathies!$B$2:$B$163,"Green",Ciliopathies!$K$2:$K$163,"Gold-standard") -> 125 | H2: =COUNTIFS(Ciliopathies!$B$2:$B$163,"Green",Ciliopathies!$K$2:$K$163,"Cilia-associated") -> 6 | I2: =COUNTIFS(Ciliopathies!$B$2:$B$163,"Green",Ciliopathies!$L$2:$L$163,"Yes") -> 126 | J2: =IF(D2=0,"",I2/D2) -> 0.96183206 | K2: =IF(D2=0,"",F2/($B$20/$B$19)) -> 6.8991023 | L2: 9.61e-112 | M2: =IF(D2=0,"",J2/($B$21/$B$19)) -> 37.109721 | N2: 1.64e-195
A3: Ciliopathies (panel 84, v2.21) | B3: Ciliary (test) | C3: Amber | D3: =COUNTIFS(Ciliopathies!$B$2:$B$163,"Amber") -> 15 | E3: =COUNTIFS(Ciliopathies!$B$2:$B$163,"Amber",Ciliopathies!$H$2:$H$163,"Yes") -> 13 | F3: =IF(D3=0,"",E3/D3) -> 0.86666667 | G3: =COUNTIFS(Ciliopathies!$B$2:$B$163,"Amber",Ciliopathies!$K$2:$K$163,"Gold-standard") -> 8 | H3: =COUNTIFS(Ciliopathies!$B$2:$B$163,"Amber",Ciliopathies!$K$2:$K$163,"Cilia-associated") -> 5 | I3: =COUNTIFS(Ciliopathies!$B$2:$B$163,"Amber",Ciliopathies!$L$2:$L$163,"Yes") -> 9 | J3: =IF(D3=0,"",I3/D3) -> 0.6 | K3: =IF(D3=0,"",F3/($B$20/$B$19)) -> 5.979222 | L3: 9.63e-10 | M3: =IF(D3=0,"",J3/($B$21/$B$19)) -> 23.149398 | N3: 3.8e-11
A4: Ciliopathies (panel 84, v2.21) | B4: Ciliary (test) | C4: Red | D4: =COUNTIFS(Ciliopathies!$B$2:$B$163,"Red") -> 16 | E4: =COUNTIFS(Ciliopathies!$B$2:$B$163,"Red",Ciliopathies!$H$2:$H$163,"Yes") -> 12 | F4: =IF(D4=0,"",E4/D4) -> 0.75 | G4: =COUNTIFS(Ciliopathies!$B$2:$B$163,"Red",Ciliopathies!$K$2:$K$163,"Gold-standard") -> 8 | H4: =COUNTIFS(Ciliopathies!$B$2:$B$163,"Red",Ciliopathies!$K$2:$K$163,"Cilia-associated") -> 4 | I4: =COUNTIFS(Ciliopathies!$B$2:$B$163,"Red",Ciliopathies!$L$2:$L$163,"Yes") -> 8 | J4: =IF(D4=0,"",I4/D4) -> 0.5 | K4: =IF(D4=0,"",F4/($B$20/$B$19)) -> 5.1743267 | L4: 8.7e-08 | M4: =IF(D4=0,"",J4/($B$21/$B$19)) -> 19.291165 | N4: 3.42e-09
A5: Ciliopathies (panel 84, v2.21) | B5: Ciliary (test) | C5: All | D5: =COUNTIFS(Ciliopathies!$B$2:$B$163,"*") -> 162 | E5: =COUNTIFS(Ciliopathies!$B$2:$B$163,"*",Ciliopathies!$H$2:$H$163,"Yes") -> 156 | F5: =IF(D5=0,"",E5/D5) -> 0.96296296 | G5: =COUNTIFS(Ciliopathies!$B$2:$B$163,"*",Ciliopathies!$K$2:$K$163,"Gold-standard") -> 141 | H5: =COUNTIFS(Ciliopathies!$B$2:$B$163,"*",Ciliopathies!$K$2:$K$163,"Cilia-associated") -> 15 | I5: =COUNTIFS(Ciliopathies!$B$2:$B$163,"*",Ciliopathies!$L$2:$L$163,"Yes") -> 143 | J5: =IF(D5=0,"",I5/D5) -> 0.88271605 | K5: =IF(D5=0,"",F5/($B$20/$B$19)) -> 6.64358 | L5: 3.17e-123 | M5: =IF(D5=0,"",J5/($B$21/$B$19)) -> 34.057241 | N5: 2.79e-208
A6: Ciliary Dyskinesia (panel 82, v2.0) | B6: Ciliary (test) | C6: Green | D6: =COUNTIFS('Ciliary Dyskinesia'!$B$2:$B$78,"Green") -> 54 | E6: =COUNTIFS('Ciliary Dyskinesia'!$B$2:$B$78,"Green",'Ciliary Dyskinesia'!$H$2:$H$78,"Yes") -> 53 | F6: =IF(D6=0,"",E6/D6) -> 0.98148148 | G6: =COUNTIFS('Ciliary Dyskinesia'!$B$2:$B$78,"Green",'Ciliary Dyskinesia'!$K$2:$K$78,"Gold-standard") -> 50 | H6: =COUNTIFS('Ciliary Dyskinesia'!$B$2:$B$78,"Green",'Ciliary Dyskinesia'!$K$2:$K$78,"Cilia-associated") -> 3 | I6: =COUNTIFS('Ciliary Dyskinesia'!$B$2:$B$78,"Green",'Ciliary Dyskinesia'!$L$2:$L$78,"Yes") -> 52 | J6: =IF(D6=0,"",I6/D6) -> 0.96296296 | K6: =IF(D6=0,"",F6/($B$20/$B$19)) -> 6.7713412 | L6: 1.08e-43 | M6: =IF(D6=0,"",J6/($B$21/$B$19)) -> 37.153354 | N6: 9.99e-80
A7: Ciliary Dyskinesia (panel 82, v2.0) | B7: Ciliary (test) | C7: Amber | D7: =COUNTIFS('Ciliary Dyskinesia'!$B$2:$B$78,"Amber") -> 10 | E7: =COUNTIFS('Ciliary Dyskinesia'!$B$2:$B$78,"Amber",'Ciliary Dyskinesia'!$H$2:$H$78,"Yes") -> 5 | F7: =IF(D7=0,"",E7/D7) -> 0.5 | G7: =COUNTIFS('Ciliary Dyskinesia'!$B$2:$B$78,"Amber",'Ciliary Dyskinesia'!$K$2:$K$78,"Gold-standard") -> 5 | H7: =COUNTIFS('Ciliary Dyskinesia'!$B$2:$B$78,"Amber",'Ciliary Dyskinesia'!$K$2:$K$78,"Cilia-associated") -> 0 | I7: =COUNTIFS('Ciliary Dyskinesia'!$B$2:$B$78,"Amber",'Ciliary Dyskinesia'!$L$2:$L$78,"Yes") -> 4 | J7: =IF(D7=0,"",I7/D7) -> 0.4 | K7: =IF(D7=0,"",F7/($B$20/$B$19)) -> 3.4495512 | L7: 0.00851 | M7: =IF(D7=0,"",J7/($B$21/$B$19)) -> 15.432932 | N7: 0.000106
A8: Ciliary Dyskinesia (panel 82, v2.0) | B8: Ciliary (test) | C8: Red | D8: =COUNTIFS('Ciliary Dyskinesia'!$B$2:$B$78,"Red") -> 13 | E8: =COUNTIFS('Ciliary Dyskinesia'!$B$2:$B$78,"Red",'Ciliary Dyskinesia'!$H$2:$H$78,"Yes") -> 13 | F8: =IF(D8=0,"",E8/D8) -> 1 | G8: =COUNTIFS('Ciliary Dyskinesia'!$B$2:$B$78,"Red",'Ciliary Dyskinesia'!$K$2:$K$78,"Gold-standard") -> 10 | H8: =COUNTIFS('Ciliary Dyskinesia'!$B$2:$B$78,"Red",'Ciliary Dyskinesia'!$K$2:$K$78,"Cilia-associated") -> 3 | I8: =COUNTIFS('Ciliary Dyskinesia'!$B$2:$B$78,"Red",'Ciliary Dyskinesia'!$L$2:$L$78,"Yes") -> 10 | J8: =IF(D8=0,"",I8/D8) -> 0.76923077 | K8: =IF(D8=0,"",F8/($B$20/$B$19)) -> 6.8991023 | L8: 1.22e-11 | M8: =IF(D8=0,"",J8/($B$21/$B$19)) -> 29.678715 | N8: 6.35e-14
A9: Ciliary Dyskinesia (panel 82, v2.0) | B9: Ciliary (test) | C9: All | D9: =COUNTIFS('Ciliary Dyskinesia'!$B$2:$B$78,"*") -> 77 | E9: =COUNTIFS('Ciliary Dyskinesia'!$B$2:$B$78,"*",'Ciliary Dyskinesia'!$H$2:$H$78,"Yes") -> 71 | F9: =IF(D9=0,"",E9/D9) -> 0.92207792 | G9: =COUNTIFS('Ciliary Dyskinesia'!$B$2:$B$78,"*",'Ciliary Dyskinesia'!$K$2:$K$78,"Gold-standard") -> 65 | H9: =COUNTIFS('Ciliary Dyskinesia'!$B$2:$B$78,"*",'Ciliary Dyskinesia'!$K$2:$K$78,"Cilia-associated") -> 6 | I9: =COUNTIFS('Ciliary Dyskinesia'!$B$2:$B$78,"*",'Ciliary Dyskinesia'!$L$2:$L$78,"Yes") -> 66 | J9: =IF(D9=0,"",I9/D9) -> 0.85714286 | K9: =IF(D9=0,"",F9/($B$20/$B$19)) -> 6.3615099 | L9: 1.27e-52 | M9: =IF(D9=0,"",J9/($B$21/$B$19)) -> 33.070568 | N9: 1.16e-92
A10: Dilated Cardiomyopathy (panel 95, v2.12) | B10: Non-ciliary (control) | C10: Green | D10: =COUNTIFS('Dilated Cardiomyopathy'!$B$2:$B$75,"Green") -> 36 | E10: =COUNTIFS('Dilated Cardiomyopathy'!$B$2:$B$75,"Green",'Dilated Cardiomyopathy'!$H$2:$H$75,"Yes") -> 8 | F10: =IF(D10=0,"",E10/D10) -> 0.22222222 | G10: =COUNTIFS('Dilated Cardiomyopathy'!$B$2:$B$75,"Green",'Dilated Cardiomyopathy'!$K$2:$K$75,"Gold-standard") -> 6 | H10: =COUNTIFS('Dilated Cardiomyopathy'!$B$2:$B$75,"Green",'Dilated Cardiomyopathy'!$K$2:$K$75,"Cilia-associated") -> 2 | I10: =COUNTIFS('Dilated Cardiomyopathy'!$B$2:$B$75,"Green",'Dilated Cardiomyopathy'!$L$2:$L$75,"Yes") -> 1 | J10: =IF(D10=0,"",I10/D10) -> 0.027777778 | K10: =IF(D10=0,"",F10/($B$20/$B$19)) -> 1.5331339 | L10: 0.141 | M10: =IF(D10=0,"",J10/($B$21/$B$19)) -> 1.0717314 | N10: 0.636
A11: Dilated Cardiomyopathy (panel 95, v2.12) | B11: Non-ciliary (control) | C11: Amber | D11: =COUNTIFS('Dilated Cardiomyopathy'!$B$2:$B$75,"Amber") -> 16 | E11: =COUNTIFS('Dilated Cardiomyopathy'!$B$2:$B$75,"Amber",'Dilated Cardiomyopathy'!$H$2:$H$75,"Yes") -> 1 | F11: =IF(D11=0,"",E11/D11) -> 0.0625 | G11: =COUNTIFS('Dilated Cardiomyopathy'!$B$2:$B$75,"Amber",'Dilated Cardiomyopathy'!$K$2:$K$75,"Gold-standard") -> 0 | H11: =COUNTIFS('Dilated Cardiomyopathy'!$B$2:$B$75,"Amber",'Dilated Cardiomyopathy'!$K$2:$K$75,"Cilia-associated") -> 1 | I11: =COUNTIFS('Dilated Cardiomyopathy'!$B$2:$B$75,"Amber",'Dilated Cardiomyopathy'!$L$2:$L$75,"Yes") -> 0 | J11: =IF(D11=0,"",I11/D11) -> 0 | K11: =IF(D11=0,"",F11/($B$20/$B$19)) -> 0.4311939 | L11: 0.919 | M11: =IF(D11=0,"",J11/($B$21/$B$19)) -> 0 | N11: 1
A12: Dilated Cardiomyopathy (panel 95, v2.12) | B12: Non-ciliary (control) | C12: Red | D12: =COUNTIFS('Dilated Cardiomyopathy'!$B$2:$B$75,"Red") -> 22 | E12: =COUNTIFS('Dilated Cardiomyopathy'!$B$2:$B$75,"Red",'Dilated Cardiomyopathy'!$H$2:$H$75,"Yes") -> 7 | F12: =IF(D12=0,"",E12/D12) -> 0.31818182 | G12: =COUNTIFS('Dilated Cardiomyopathy'!$B$2:$B$75,"Red",'Dilated Cardiomyopathy'!$K$2:$K$75,"Gold-standard") -> 4 | H12: =COUNTIFS('Dilated Cardiomyopathy'!$B$2:$B$75,"Red",'Dilated Cardiomyopathy'!$K$2:$K$75,"Cilia-associated") -> 3 | I12: =COUNTIFS('Dilated Cardiomyopathy'!$B$2:$B$75,"Red",'Dilated Cardiomyopathy'!$L$2:$L$75,"Yes") -> 1 | J12: =IF(D12=0,"",I12/D12) -> 0.045454545 | K12: =IF(D12=0,"",F12/($B$20/$B$19)) -> 2.1951689 | L12: 0.0311 | M12: =IF(D12=0,"",J12/($B$21/$B$19)) -> 1.7537422 | N12: 0.46
A13: Dilated Cardiomyopathy (panel 95, v2.12) | B13: Non-ciliary (control) | C13: All | D13: =COUNTIFS('Dilated Cardiomyopathy'!$B$2:$B$75,"*") -> 74 | E13: =COUNTIFS('Dilated Cardiomyopathy'!$B$2:$B$75,"*",'Dilated Cardiomyopathy'!$H$2:$H$75,"Yes") -> 16 | F13: =IF(D13=0,"",E13/D13) -> 0.21621622 | G13: =COUNTIFS('Dilated Cardiomyopathy'!$B$2:$B$75,"*",'Dilated Cardiomyopathy'!$K$2:$K$75,"Gold-standard") -> 10 | H13: =COUNTIFS('Dilated Cardiomyopathy'!$B$2:$B$75,"*",'Dilated Cardiomyopathy'!$K$2:$K$75,"Cilia-associated") -> 6 | I13: =COUNTIFS('Dilated Cardiomyopathy'!$B$2:$B$75,"*",'Dilated Cardiomyopathy'!$L$2:$L$75,"Yes") -> 2 | J13: =IF(D13=0,"",I13/D13) -> 0.027027027 | K13: =IF(D13=0,"",F13/($B$20/$B$19)) -> 1.4916978 | L13: 0.0627 | M13: =IF(D13=0,"",J13/($B$21/$B$19)) -> 1.0427657 | N13: 0.61
A19: Gene universe (protein-coding genes, Table S1) | B19: 19214
A20: CiliaHub v9.2 genes | B20: 2785
A21: Ciliopathy module genes (linked to ≥1 ciliopathy; genes linked only to secondary disorders excluded) | B21: 498
A23: Primary analysis rows (Green = diagnostic-grade) are in bold. Counts, percentages and fold enrichments are live formulas over the panel sheets; one-sided Fisher exact P values (scipy.stats.fisher_exact, alternative="greater", against the 19,214-gene universe) are static values.

Sheet Ciliopathies
A1: Gene symbol (panel) | B1: PanelApp rating | C1: Mode of inheritance | D1: Phenotypes (panel) | E1: Ensembl ID GRCh38 (panel) | F1: HGNC ID (panel) | G1: Panel sources | H1: In CiliaHub | I1: CiliaHub gene | J1: Match method | K1: CiliaHub category | L1: In ciliopathy module | M1: CiliaHub ciliopathies | N1: CiliaHub ciliopathy classification | O1: CiliaHub localization | P1: Note
A2: AHI1 | B2: Green | C2: BIALLELIC, autosomal or pseudoautosomal | D2: Joubert syndrome 3, MIM# 608629 | E2: ENSG00000135541 | F2: HGNC:21575 | G2: Expert Review Green;Victorian Clinical Genetics Services | H2: Yes | I2: AHI1 | J2: Ensembl ID | K2: Gold-standard | L2: Yes | M2: Joubert Syndrome; Nephronophthisis | N2: Primary Ciliopathies | O2: basal body; centrosome; cilia | P2: Modifier: in one acrocallosal syndrome family with a homozygous KIF7 deletion, an additional AHI1 (p.R830W) variant was proposed as an oligogenic contributor to phenotypic variability (PMID 23142271).
A3: ALMS1 | B3: Green | C3: BIALLELIC, autosomal or pseudoautosomal | D3: Alstrom syndrome, MIM# 203800 | E3: ENSG00000116127 | F3: HGNC:428 | G3: Expert Review Green;Victorian Clinical Genetics Services | H3: Yes | I3: ALMS1 | J3: Ensembl ID | K3: Gold-standard | L3: Yes | M3: Alström Syndrome | N3: Primary Ciliopathies | O3: basal body; centrosome; cilia; cytosol
A4: ANKS6 | B4: Green | C4: BIALLELIC, autosomal or pseudoautosomal | D4: Nephronophthisis 16, MIM# 615382;MONDO:0014158 | E4: ENSG00000165138 | F4: HGNC:26724 | G4: Expert Review Green;Victorian Clinical Genetics Services | H4: Yes | I4: ANKS6 | J4: Ensembl ID | K4: Gold-standard | L4: Yes | M4: Nephronophthisis; Polycystic Kidney Disease | N4: Primary Ciliopathies; Tissue-restricted Ciliopathies | O4: cilia
A5: ARL13B | B5: Green | C5: BIALLELIC, autosomal or pseudoautosomal | D5: Joubert syndrome 8, MIM# 612291 | E5: ENSG00000169379 | F5: HGNC:25419 | G5: Expert Review Green;Victorian Clinical Genetics Services | H5: Yes | I5: ARL13B | J5: Ensembl ID | K5: Gold-standard | L5: Yes | M5: Joubert Syndrome | N5: Primary Ciliopathies | O5: cilia
A6: ARL3 | B6: Green | C6: BIALLELIC, autosomal or pseudoautosomal | D6: Joubert syndrome 35 MIM#618161 | E6: ENSG00000138175 | F6: HGNC:694 | G6: Expert Review Green;Literature | H6: Yes | I6: ARL3 | J6: Ensembl ID | K6: Gold-standard | L6: Yes | M6: Autosomal Recessive Polycystic Kidney Disease; Cone-Rod Dystrophy; Joubert Syndrome; Retinal Dystrophy/Degeneration | N6: Tissue-restricted Ciliopathies; Primary Ciliopathies | O6: basal body; centrosome; nucleus
A7: ARL6 | B7: Green | C7: BIALLELIC, autosomal or pseudoautosomal | D7: Bardet-Biedl syndrome 3, MIM# 600151;Retinitis pigmentosa 55, MIM# 613575 | E7: ENSG00000113966 | F7: HGNC:13210 | G7: Expert Review Green;Victorian Clinical Genetics Services | H7: Yes | I7: ARL6 | J7: Ensembl ID | K7: Gold-standard | L7: Yes | M7: Bardet-Biedl Syndrome; Retinal Dystrophy/Degeneration | N7: Primary Ciliopathies; Tissue-restricted Ciliopathies | O7: basal body; cilia; transition zone
A8: ARMC9 | B8: Green | C8: BIALLELIC, autosomal or pseudoautosomal | D8: Joubert syndrome 30 617622 AR | E8: ENSG00000135931 | F8: HGNC:20730 | G8: Expert list;Expert Review Green | H8: Yes | I8: ARMC9 | J8: Ensembl ID | K8: Gold-standard | L8: Yes | M8: Joubert Syndrome | N8: Primary Ciliopathies | O8: basal body; cilia
A9: B9D1 | B9: Green | C9: BIALLELIC, autosomal or pseudoautosomal | D9: Ciliopathy, MONDO:0005308, B9D1-related | E9: ENSG00000108641 | F9: HGNC:24123 | G9: Expert Review Green;Victorian Clinical Genetics Services | H9: Yes | I9: B9D1 | J9: Ensembl ID | K9: Gold-standard | L9: Yes | M9: Joubert Syndrome; Meckel-Gruber Syndrome | N9: Primary Ciliopathies | O9: basal body; centrosome; transition zone
A10: B9D2 | B10: Green | C10: BIALLELIC, autosomal or pseudoautosomal | D10: Joubert syndrome 34, MIM# 614175;Meckel syndrome 10, MIM# 614175 | E10: ENSG00000123810 | F10: HGNC:28636 | G10: Expert Review Green;Victorian Clinical Genetics Services | H10: Yes | I10: B9D2 | J10: Ensembl ID | K10: Gold-standard | L10: Yes | M10: Joubert Syndrome; Meckel-Gruber Syndrome; Nephronophthisis | N10: Primary Ciliopathies | O10: basal body; centrosome; cytosol; nucleus; transition zone
A11: BBIP1 | B11: Green | C11: BIALLELIC, autosomal or pseudoautosomal | D11: Bardet-Biedl syndrome 18, MIM#615995 | E11: ENSG00000214413 | F11: HGNC:28093 | G11: Expert list;Expert Review Green | H11: Yes | I11: BBIP1 | J11: Ensembl ID | K11: Gold-standard | L11: Yes | M11: Bardet-Biedl Syndrome | N11: Primary Ciliopathies | O11: basal body; cilia
A12: BBS1 | B12: Green | C12: BIALLELIC, autosomal or pseudoautosomal | D12: Bardet-Biedl syndrome 1, MIM# 209900 | E12: ENSG00000174483 | F12: HGNC:966 | G12: Expert Review Green;Victorian Clinical Genetics Services | H12: Yes | I12: BBS1 | J12: Ensembl ID | K12: Gold-standard | L12: Yes | M12: Bardet-Biedl Syndrome; Cranioectodermal Dysplasia (Sensenbrenner) | N12: Primary Ciliopathies | O12: basal body; cilia; nucleus
A13: BBS10 | B13: Green | C13: BIALLELIC, autosomal or pseudoautosomal | D13: Bardet-Biedl syndrome 10, MIM# 615987 | E13: ENSG00000179941 | F13: HGNC:26291 | G13: Expert Review Green;Victorian Clinical Genetics Services | H13: Yes | I13: BBS10 | J13: Ensembl ID | K13: Gold-standard | L13: Yes | M13: Bardet-Biedl Syndrome | N13: Primary Ciliopathies | O13: basal body
A14: BBS12 | B14: Green | C14: BIALLELIC, autosomal or pseudoautosomal | D14: Bardet-Biedl syndrome 12, MIM# 615989 | E14: ENSG00000181004 | F14: HGNC:26648 | G14: Expert Review Green;Victorian Clinical Genetics Services | H14: Yes | I14: BBS12 | J14: Ensembl ID | K14: Gold-standard | L14: Yes | M14: Bardet-Biedl Syndrome | N14: Primary Ciliopathies | O14: basal body
A15: BBS2 | B15: Green | C15: BIALLELIC, autosomal or pseudoautosomal | D15: Bardet-Biedl syndrome 2, MIM# 615981;Retinitis pigmentosa 74, MIM# 616562 | E15: ENSG00000125124 | F15: HGNC:967 | G15: Expert Review Green;Victorian Clinical Genetics Services | H15: Yes | I15: BBS2 | J15: Ensembl ID | K15: Gold-standard | L15: Yes | M15: Bardet-Biedl Syndrome; Retinal Dystrophy/Degeneration | N15: Primary Ciliopathies; Tissue-restricted Ciliopathies | O15: basal body; cilia; transition zone | P15: Modifier: in one acrocallosal syndrome family with a homozygous KIF7 deletion, an additional BBS2 (p.N70S) variant was proposed as an oligogenic contributor to phenotypic variability (PMID 23142271).
A16: BBS4 | B16: Green | C16: BIALLELIC, autosomal or pseudoautosomal | D16: Bardet-Biedl syndrome 4, MIM#615982;MONDO:0014433 | E16: ENSG00000140463 | F16: HGNC:969 | G16: Expert Review Green;Victorian Clinical Genetics Services | H16: Yes | I16: BBS4 | J16: Ensembl ID | K16: Gold-standard | L16: Yes | M16: Bardet-Biedl Syndrome | N16: Primary Ciliopathies | O16: basal body; centrosome; cilia | P16: Modifier: in one acrocallosal syndrome family with a homozygous KIF7 deletion, an additional BBS4 (p.M472V) variant was proposed as an oligogenic contributor to phenotypic variability (PMID 23142271).
A17: BBS5 | B17: Green | C17: BIALLELIC, autosomal or pseudoautosomal | D17: Bardet-Biedl syndrome 5, MIM#615983;MONDO:0014434 | E17: ENSG00000163093 | F17: HGNC:970 | G17: Expert Review Green;Victorian Clinical Genetics Services | H17: Yes | I17: BBS5 | J17: Ensembl ID | K17: Gold-standard | L17: Yes | M17: Bardet-Biedl Syndrome | N17: Primary Ciliopathies | O17: basal body
A18: BBS7 | B18: Green | C18: BIALLELIC, autosomal or pseudoautosomal | D18: Bardet-Biedl syndrome 7, MIM# 615984;MONDO:0014435 | E18: ENSG00000138686 | F18: HGNC:18758 | G18: Expert Review Green;Victorian Clinical Genetics Services | H18: Yes | I18: BBS7 | J18: Ensembl ID | K18: Gold-standard | L18: Yes | M18: Bardet-Biedl Syndrome | N18: Primary Ciliopathies | O18: basal body; centrosome; cilia; nucleus
A19: BBS9 | B19: Green | C19: BIALLELIC, autosomal or pseudoautosomal | D19: Bardet-Biedl syndrome 9, MIM#615986;MONDO:0014437 | E19: ENSG00000122507 | F19: HGNC:30000 | G19: Expert Review Green;Victorian Clinical Genetics Services | H19: Yes | I19: BBS9 | J19: Ensembl ID | K19: Gold-standard | L19: Yes | M19: Bardet-Biedl Syndrome | N19: Primary Ciliopathies | O19: cilia
A20: C2CD3 | B20: Green | C20: BIALLELIC, autosomal or pseudoautosomal | D20: Orofaciodigital syndrome XIV, MIM# 615948;MONDO:0014413 | E20: ENSG00000168014 | F20: HGNC:24564 | G20: Expert list;Expert Review Green;Victorian Clinical Genetics Services | H20: Yes | I20: C2CD3 | J20: Ensembl ID | K20: Gold-standard | L20: Yes | M20: Orofaciodigital Syndrome | N20: Primary Ciliopathies | O20: basal body; centrosome
A21: CBY1 | B21: Green | C21: BIALLELIC, autosomal or pseudoautosomal | D21: intellectual disability;cerebellar ataxia;molar tooth sign;polydactyly;Joubert syndrome | E21: ENSG00000100211 | F21: HGNC:1307 | G21: Expert Review Green;Literature | H21: Yes | I21: CBY1 | J21: Ensembl ID | K21: Gold-standard | L21: Yes | M21: Joubert Syndrome | N21: Primary Ciliopathies | O21: basal body; nucleus; transition zone
A22: CC2D2A | B22: Green | C22: BIALLELIC, autosomal or pseudoautosomal | D22: COACH syndrome 2, MIM# 619111;Joubert syndrome 9, 612285;Meckel syndrome 6, 612284 | E22: ENSG00000048342 | F22: HGNC:29253 | G22: Expert Review Green;Victorian Clinical Genetics Services | H22: Yes | I22: CC2D2A | J22: Ensembl ID | K22: Gold-standard | L22: Yes | M22: COACH Syndrome; Joubert Syndrome; Meckel-Gruber Syndrome; Nephronophthisis | N22: Primary Ciliopathies | O22: basal body; cilia; transition zone
A23: CCDC32 | B23: Green | C23: BIALLELIC, autosomal or pseudoautosomal | D23: Cardiofacioneurodevelopmental syndrome (CFNDS), MIM#619123;Craniofacial, cardiac, laterality and neurodevelopmental anomalies | E23: ENSG00000128891 | F23: HGNC:28295 | G23: Expert Review Green;Literature | H23: Yes | I23: CCDC32 | J23: Ensembl ID | K23: Gold-standard | L23: No | O23: basal body
A24: CDK20 | B24: Green | C24: BIALLELIC, autosomal or pseudoautosomal | D24: Lemire-Marshall-Drivas-Chitayat syndrome, MIM# 621676 | E24: ENSG00000156345 | F24: HGNC:21420 | G24: Expert Review Green;Literature | H24: Yes | I24: CDK20 | J24: Ensembl ID | K24: Gold-standard | L24: Yes | M24: CDK20-related Ciliopathy with Midline Brain and Facial Anomalies | N24: Primary Ciliopathies | O24: cilia; nucleus
A25: CENPF | B25: Green | C25: BIALLELIC, autosomal or pseudoautosomal | D25: Stromme syndrome (MIM#243605) | E25: ENSG00000117724 | F25: HGNC:1857 | G25: Expert Review Green;Victorian Clinical Genetics Services | H25: Yes | I25: CENPF | J25: Ensembl ID | K25: Gold-standard | L25: Yes | M25: Stromme Syndrome | N25: Primary Ciliopathies | O25: basal body; cilia; cytosol; nucleus
A26: CEP104 | B26: Green | C26: BIALLELIC, autosomal or pseudoautosomal | D26: Joubert syndrome 25, MIM# 616781;MONDO:0014770 | E26: ENSG00000116198 | F26: HGNC:24866 | G26: Expert list;Expert Review Green;Victorian Clinical Genetics Services | H26: Yes | I26: CEP104 | J26: Ensembl ID | K26: Gold-standard | L26: Yes | M26: Intellectual Developmental Disorder; Joubert Syndrome | N26: Tissue-restricted Ciliopathies; Primary Ciliopathies | O26: basal body; centrosome; cilia; ciliary tip
A27: CEP120 | B27: Green | C27: BIALLELIC, autosomal or pseudoautosomal | D27: Joubert syndrome 31, MIM# 617761;Short-rib thoracic dysplasia 13 with or without polydactyly, MIM# 616300 | E27: ENSG00000168944 | F27: HGNC:26690 | G27: Expert list;Expert Review Green;Victorian Clinical Genetics Services | H27: Yes | I27: CEP120 | J27: Ensembl ID | K27: Gold-standard | L27: Yes | M27: Hydrolethalus Syndrome; Joubert Syndrome; Short-Rib Thoracic Dysplasia | N27: Primary Ciliopathies | O27: basal body; centrosome
A28: CEP164 | B28: Green | C28: BIALLELIC, autosomal or pseudoautosomal | D28: Bardet-Biedl syndrome;Nephronophthisis 15, MIM# 614845;Oro-facio-digital syndrome | E28: ENSG00000110274 | F28: HGNC:29182 | G28: Expert list;Expert Review Green;Victorian Clinical Genetics Services | H28: Yes | I28: CEP164 | J28: Ensembl ID | K28: Gold-standard | L28: Yes | M28: Joubert Syndrome; Nephronophthisis; Senior-Løken Syndrome | N28: Primary Ciliopathies | O28: basal body; centrosome; cytosol; nucleus
A29: CEP290 | B29: Green | C29: BIALLELIC, autosomal or pseudoautosomal | D29: Bardet-Biedl syndrome 14, MIM# 615991;Joubert syndrome 5 610188;Leber congenital amaurosis 10, MIM# 611755;Meckel syndrome 4, MIM# 611134;Senior-Loken syndrome 6, MIM# 610189 | E29: ENSG00000198707 | F29: HGNC:29021 | G29: Expert Review Green;Victorian Clinical Genetics Services | H29: Yes | I29: CEP290 | J29: Ensembl ID | K29: Gold-standard | L29: Yes | M29: Bardet-Biedl Syndrome; COACH Syndrome; Joubert Syndrome; Leber Congenital Amaurosis; Meckel-Gruber Syndrome; Nephronophthisis; Senior-Løken Syndrome | N29: Primary Ciliopathies; Tissue-restricted Ciliopathies | O29: basal body; centrosome; cytosol; nucleus; transition zone
A30: CEP41 | B30: Green | C30: BIALLELIC, autosomal or pseudoautosomal | D30: Joubert syndrome 15, MIM# 614464 | E30: ENSG00000106477 | F30: HGNC:12370 | G30: Expert Review Green;Victorian Clinical Genetics Services | H30: Yes | I30: CEP41 | J30: Ensembl ID | K30: Gold-standard | L30: Yes | M30: Autism Spectrum Disorder; Joubert Syndrome | N30: Secondary Diseases; Primary Ciliopathies | O30: basal body; centrosome; cytosol
A31: CEP76 | B31: Green | C31: BIALLELIC, autosomal or pseudoautosomal | D31: complex neurodevelopmental disorder MONDO:0100038;Joubert syndrome;Bardet-Biedl syndrome;retinitis pigmentosa | E31: ENSG00000101624 | F31: HGNC:25727 | G31: Expert Review Green;Other | H31: Yes | I31: CEP76 | J31: Ensembl ID | K31: Gold-standard | L31: Yes | M31: Joubert Syndrome | N31: Primary Ciliopathies | O31: centrosome; cilia; cytosol
A32: CEP83 | B32: Green | C32: BIALLELIC, autosomal or pseudoautosomal | D32: Nephronophthisis 18, MIM# 615862;MONDO:0014374;Retinal dystrophy;ID | E32: ENSG00000173588 | F32: HGNC:17966 | G32: Expert Review Green;Victorian Clinical Genetics Services | H32: Yes | I32: CEP83 | J32: Ensembl ID | K32: Gold-standard | L32: Yes | M32: Joubert Syndrome; Nephronophthisis; Orofaciodigital Syndrome; Retinal Dystrophy/Degeneration | N32: Primary Ciliopathies; Tissue-restricted Ciliopathies | O32: basal body; centrosome
A33: CFAP410 | B33: Green | C33: BIALLELIC, autosomal or pseudoautosomal | D33: Spondylometaphyseal dysplasia, axial, MIM# 602271;Retinal dystrophy with macular staphyloma, MIM# 617547 | E33: ENSG00000160226 | F33: HGNC:1260 | G33: Expert Review Green;Victorian Clinical Genetics Services | H33: Yes | I33: CFAP410 | J33: Ensembl ID | K33: Gold-standard | L33: Yes | M33: Cone-Rod Dystrophy; Retinal Dystrophy/Degeneration; Skeletal Ciliopathy; Spondylometaphyseal Dysplasia | N33: Tissue-restricted Ciliopathies | O33: basal body
A34: CFAP418 | B34: Green | C34: BIALLELIC, autosomal or pseudoautosomal | D34: Bardet-Biedl syndrome 21, MIM#617406;Retinitis pigmentosa 64, MIM#614500 | E34: ENSG00000156172 | F34: HGNC:27232 | G34: Expert list;Expert Review Green | H34: Yes | I34: CFAP418 | J34: Ensembl ID | K34: Gold-standard | L34: Yes | M34: Bardet-Biedl Syndrome; Cone-Rod Dystrophy; Retinal Dystrophy/Degeneration | N34: Primary Ciliopathies; Tissue-restricted Ciliopathies | O34: basal body
A35: CILK1 | B35: Green | C35: BIALLELIC, autosomal or pseudoautosomal | D35: Endocrine-cerebroosteodysplasia (MIM#612651);Cranioectodermal dysplasia 6, MIM# 621337 | E35: ENSG00000112144 | F35: HGNC:21219 | G35: Expert Review;Expert Review Green | H35: Yes | I35: CILK1 | J35: Ensembl ID | K35: Gold-standard | L35: Yes | M35: Cranioectodermal Dysplasia (Sensenbrenner); Endocrine-Cerebro-Osteodysplasia Syndrome; Juvenile Myoclonic Epilepsy; Short-Rib Thoracic Dysplasia | N35: Primary Ciliopathies; Tissue-restricted Ciliopathies | O35: cilia tip; primary cilium; basal body; intraflagellar transport
... A37: CPLANE2 | B37: Green | C37: BIALLELIC, autosomal or pseudoautosomal | D37: Ciliopathy, MONDO:0005308, CPLANE2-related | E37: ENSG00000132881 | F37: HGNC:28127 | G37: Expert Review Green;Literature | H37: Yes | I37: CPLANE2 | J37: Ensembl ID | K37: Gold-standard | L37: Yes | M37: Biliary Atresia; Orofaciodigital Syndrome | N37: Tissue-restricted Ciliopathies; Primary Ciliopathies | O37: basal body; transition zone
A38: CRB2 | B38: Green | C38: BIALLELIC, autosomal or pseudoautosomal | D38: Ventriculomegaly with cystic kidney disease, MIM# 219730 | E38: ENSG00000148204 | F38: HGNC:18688 | G38: Expert Review Green;Victorian Clinical Genetics Services | H38: Yes | I38: CRB2 | J38: Ensembl ID | K38: Cilia-associated | L38: No | O38: cilia associated gene
A39: CSPP1 | B39: Green | C39: BIALLELIC, autosomal or pseudoautosomal | D39: Joubert syndrome 21, MIM# 615636;MONDO:0014288 | E39: ENSG00000104218 | F39: HGNC:26193 | G39: Expert Review Green;Victorian Clinical Genetics Services | H39: Yes | I39: CSPP1 | J39: Ensembl ID | K39: Gold-standard | L39: Yes | M39: Joubert Syndrome | N39: Primary Ciliopathies | O39: basal body; centrosome; cilia; microtubules; transition zone
A40: DCDC2 | B40: Green | C40: BIALLELIC, autosomal or pseudoautosomal | D40: Nephronophthisis 19, MIM# 616217 | E40: ENSG00000146038 | F40: HGNC:18141 | G40: Expert Review Green;Victorian Clinical Genetics Services | H40: Yes | I40: DCDC2 | J40: Ensembl ID | K40: Gold-standard | L40: Yes | M40: Neonatal Sclerosing Cholangitis; Nephronophthisis | N40: Tissue-restricted Ciliopathies; Primary Ciliopathies | O40: cilia; microtubules
A41: DDX59 | B41: Green | C41: BIALLELIC, autosomal or pseudoautosomal | D41: Orofaciodigital syndrome V (MIM#174300) | E41: ENSG00000118197 | F41: HGNC:25360 | G41: Expert Review;Expert Review Green;Victorian Clinical Genetics Services | H41: Yes | I41: DDX59 | J41: Ensembl ID | K41: Gold-standard | L41: Yes | M41: Orofaciodigital Syndrome | N41: Primary Ciliopathies | O41: basal body; nucleus | P41: Homozygous DDX59 variants were reported in 2 consanguineous families with OFD (PMID 23972372) and in 2 further unrelated consanguineous families (PMID 28711741).
...

Sheet Ciliary Dyskinesia
A1: Gene symbol (panel) | B1: PanelApp rating | C1: Mode of inheritance | D1: Phenotypes (panel) | E1: Ensembl ID GRCh38 (panel) | F1: HGNC ID (panel) | G1: Panel sources | H1: In CiliaHub | I1: CiliaHub gene | J1: Match method | K1: CiliaHub category | L1: In ciliopathy module | M1: CiliaHub ciliopathies | N1: CiliaHub ciliopathy classification | O1: CiliaHub localization | P1: Note
A2: AGR2 | B2: Green | C2: BIALLELIC, autosomal or pseudoautosomal | D2: Recurrent respiratory infections and failure to thrive with or without diarrhea (RIFTD), MIM#620233 | E2: ENSG00000106541 | F2: HGNC:328 | G2: Expert Review Green;Literature | H2: No | J2: Not found | K2: Not in CiliaHub | L2: No
A3: CCDC39 | B3: Green | C3: BIALLELIC, autosomal or pseudoautosomal | D3: Ciliary dyskinesia, primary, 14, MIM# 613807 | E3: ENSG00000284862 | F3: HGNC:25244 | G3: Expert Review Green;Victorian Clinical Genetics Services | H3: Yes | I3: CCDC39 | J3: Ensembl ID | K3: Gold-standard | L3: Yes | M3: Mucociliary Clearance Disorder; Primary Ciliary Dyskinesia | N3: Motile Ciliopathies | O3: cilia
A4: CCDC40 | B4: Green | C4: BIALLELIC, autosomal or pseudoautosomal | D4: Ciliary dyskinesia, primary, 15, MIM#613808 | E4: ENSG00000141519 | F4: HGNC:26090 | G4: Expert Review Green;Victorian Clinical Genetics Services | H4: Yes | I4: CCDC40 | J4: Ensembl ID | K4: Gold-standard | L4: Yes | M4: Primary Ciliary Dyskinesia | N4: Motile Ciliopathies | O4: cilia; microtubules
A5: CCNO | B5: Green | C5: BIALLELIC, autosomal or pseudoautosomal | D5: Ciliary dyskinesia, primary, 29, MIM# 615872 | E5: ENSG00000152669 | F5: HGNC:18576 | G5: Expert Review Green;Victorian Clinical Genetics Services | H5: Yes | I5: CCNO | J5: Ensembl ID | K5: Gold-standard | L5: Yes | M5: Mucociliary Clearance Disorder; Primary Ciliary Dyskinesia | N5: Motile Ciliopathies | O5: basal body; nucleus
A6: CFAP221 | B6: Green | C6: BIALLELIC, autosomal or pseudoautosomal | D6: Ciliary dyskinesia, primary, 55, MIM# 279000 | E6: ENSG00000163075 | F6: HGNC:33720 | G6: Expert Review Green;Literature | H6: Yes | I6: CFAP221 | J6: Ensembl ID | K6: Gold-standard | L6: Yes | M6: Primary Ciliary Dyskinesia | N6: Motile Ciliopathies | O6: cilia
A7: CFAP298 | B7: Green | C7: BIALLELIC, autosomal or pseudoautosomal | D7: Ciliary dyskinesia, primary, 26, MIM# 615500 | E7: ENSG00000159079 | F7: HGNC:1301 | G7: Expert Review Green;Victorian Clinical Genetics Services | H7: Yes | I7: CFAP298 | J7: Ensembl ID | K7: Gold-standard | L7: Yes | M7: Primary Ciliary Dyskinesia | N7: Motile Ciliopathies | O7: basal body; cilia; transition zone
A8: CFAP300 | B8: Green | C8: BIALLELIC, autosomal or pseudoautosomal | D8: Ciliary dyskinesia, primary, 38 618063 | E8: ENSG00000137691 | F8: HGNC:28188 | G8: Expert list;Expert Review Green | H8: Yes | I8: CFAP300 | J8: Ensembl ID | K8: Gold-standard | L8: Yes | M8: Male Infertility; Primary Ciliary Dyskinesia | N8: Motile Ciliopathies | O8: cilia
A9: CFAP53 | B9: Green | C9: BIALLELIC, autosomal or pseudoautosomal | D9: Heterotaxy, visceral, 6, autosomal recessive 614779 | E9: ENSG00000172361 | F9: HGNC:26530 | G9: Expert Review Green;Literature | H9: Yes | I9: CFAP53 | J9: Ensembl ID | K9: Gold-standard | L9: Yes | M9: Visceral Heterotaxy / Situs Inversus | N9: Motile Ciliopathies | O9: basal body
A10: CFAP54 | B10: Green | C10: BIALLELIC, autosomal or pseudoautosomal | D10: Spermatogenic failure 98, MIM# 621124;Ciliary dyskinesia, primary, 54, MIM# 621125 | E10: ENSG00000188596 | F10: HGNC:26456 | G10: Expert Review Green;Literature | H10: Yes | I10: CFAP54 | J10: Ensembl ID | K10: Gold-standard | L10: Yes | M10: Primary Ciliary Dyskinesia | N10: Motile Ciliopathies | O10: cilia
A11: CFAP74 | B11: Green | C11: BIALLELIC, autosomal or pseudoautosomal | D11: ciliary dyskinesia, primary, 49, without situs inversus MONDO:0859353 | E11: ENSG00000142609 | F11: HGNC:29368 | G11: Expert Review Green;Literature | H11: Yes | I11: CFAP74 | J11: Ensembl ID | K11: Gold-standard | L11: Yes | M11: Primary Ciliary Dyskinesia | N11: Motile Ciliopathies | O11: cilia
A12: CFTR | B12: Green | C12: BIALLELIC, autosomal or pseudoautosomal | D12: Cystic fibrosis;bronchiectasis | E12: ENSG00000001626 | F12: HGNC:1884 | G12: Expert list;Expert Review Green | H12: Yes | I12: CFTR | J12: Ensembl ID | K12: Gold-standard | L12: No | O12: cilia; endosome; microtubules
A13: CLXN | B13: Green | C13: BIALLELIC, autosomal or pseudoautosomal | D13: Ciliary dyskinesia, primary, 53, MIM# 620642 | E13: ENSG00000034239 | F13: HGNC:25678 | G13: Expert Review Green;Literature | H13: Yes | I13: CLXN | J13: Ensembl ID | K13: Gold-standard | L13: Yes | M13: Primary Ciliary Dyskinesia | N13: Motile Ciliopathies | O13: cilia
A14: DAW1 | B14: Green | C14: BIALLELIC, autosomal or pseudoautosomal | D14: Primary ciliary dyskinesia, with or without heterotaxy, MIM#620570 | E14: ENSG00000123977 | F14: HGNC:26383 | G14: Expert Review Green;Literature | H14: Yes | I14: DAW1 | J14: Ensembl ID | K14: Gold-standard | L14: Yes | M14: Primary Ciliary Dyskinesia; Visceral Heterotaxy / Situs Inversus | N14: Motile Ciliopathies | O14: basal body; flagella | P14: Compound heterozygous DAW1 variants were reported in a single proband with heterotaxy spectrum and complex congenital heart disease without PCD, with functional support from Xenopus (PMID 42773161).
A15: DNAAF1 | B15: Green | C15: BIALLELIC, autosomal or pseudoautosomal | D15: Ciliary dyskinesia, primary, 13, MIM# 613193 | E15: ENSG00000154099 | F15: HGNC:30539 | G15: Expert Review Green;Victorian Clinical Genetics Services | H15: Yes | I15: DNAAF1 | J15: Ensembl ID | K15: Gold-standard | L15: Yes | M15: Primary Ciliary Dyskinesia | N15: Motile Ciliopathies | O15: basal body; cilia; nucleus
A16: DNAAF11 | B16: Green | C16: BIALLELIC, autosomal or pseudoautosomal | D16: Ciliary dyskinesia, primary, 19, MIM# 614935 | E16: ENSG00000129295 | F16: HGNC:16725 | G16: Expert Review Green;Victorian Clinical Genetics Services | H16: Yes | I16: DNAAF11 | J16: Ensembl ID | K16: Gold-standard | L16: Yes | M16: Male Infertility; Primary Ciliary Dyskinesia | N16: Motile Ciliopathies | O16: flagella; cilia; cytosol
A17: DNAAF19 | B17: Green | C17: BIALLELIC, autosomal or pseudoautosomal | D17: Ciliary dyskinesia, primary, 17, MIM# 614679 | E17: ENSG00000167131 | F17: HGNC:32700 | G17: Expert Review Green;Victorian Clinical Genetics Services | H17: Yes | I17: DNAAF19 | J17: Ensembl ID | K17: Gold-standard | L17: Yes | M17: Primary Ciliary Dyskinesia | N17: Motile Ciliopathies | O17: cilia
A18: DNAAF2 | B18: Green | C18: BIALLELIC, autosomal or pseudoautosomal | D18: Ciliary dyskinesia, primary, 10, MIM# 612518 | E18: ENSG00000165506 | F18: HGNC:20188 | G18: Expert Review Green;Victorian Clinical Genetics Services | H18: Yes | I18: DNAAF2 | J18: Ensembl ID | K18: Gold-standard | L18: Yes | M18: Primary Ciliary Dyskinesia | N18: Motile Ciliopathies | O18: basal body
A19: DNAAF3 | B19: Green | C19: BIALLELIC, autosomal or pseudoautosomal | D19: Ciliary dyskinesia, primary, 2, MIM# 606763 | E19: ENSG00000167646 | F19: HGNC:30492 | G19: Expert Review Green;Victorian Clinical Genetics Services | H19: Yes | I19: DNAAF3 | J19: Ensembl ID | K19: Cilia-associated | L19: Yes | M19: Primary Ciliary Dyskinesia | N19: Motile Ciliopathies | O19: cilia associated gene
A20: DNAAF4 | B20: Green | C20: BIALLELIC, autosomal or pseudoautosomal | D20: Ciliary dyskinesia, primary, 25, MIM# 615482 | E20: ENSG00000256061 | F20: HGNC:21493 | G20: Expert Review Green;Victorian Clinical Genetics Services | H20: Yes | I20: DNAAF4 | J20: Ensembl ID | K20: Gold-standard | L20: Yes | M20: Primary Ciliary Dyskinesia | N20: Motile Ciliopathies | O20: basal body
A21: DNAAF5 | B21: Green | C21: BIALLELIC, autosomal or pseudoautosomal | D21: Ciliary dyskinesia, primary, 18, MIM# 614874 | E21: ENSG00000164818 | F21: HGNC:26013 | G21: Expert Review Green;Victorian Clinical Genetics Services | H21: Yes | I21: DNAAF5 | J21: Ensembl ID | K21: Cilia-associated | L21: Yes | M21: Primary Ciliary Dyskinesia | N21: Motile Ciliopathies | O21: cilia associated gene
A22: DNAAF6 | B22: Green | C22: X-LINKED: hemizygous mutation in males, biallelic mutations in females | D22: Ciliary dyskinesia, primary, 36, X-linked (MIM#300991) | E22: ENSG00000080572 | F22: HGNC:28570 | G22: Expert Review Green;Victorian Clinical Genetics Services | H22: Yes | I22: DNAAF6 | J22: Ensembl ID | K22: Gold-standard | L22: Yes | M22: Primary Ciliary Dyskinesia | N22: Motile Ciliopathies | O22: basal body; cilia
A23: DNAH11 | B23: Green | C23: BIALLELIC, autosomal or pseudoautosomal | D23: Ciliary dyskinesia, primary, 7, with or without situs inversus, MIM#611884 | E23: ENSG00000105877 | F23: HGNC:2942 | G23: Expert Review Green;Victorian Clinical Genetics Services | H23: Yes | I23: DNAH11 | J23: Ensembl ID | K23: Gold-standard | L23: Yes | M23: Primary Ciliary Dyskinesia; Visceral Heterotaxy / Situs Inversus | N23: Motile Ciliopathies | O23: cilia; flagella; microtubules
A24: DNAH17 | B24: Green | C24: BIALLELIC, autosomal or pseudoautosomal | D24: spermatogenic failure 39 (MONDO:0032845) | E24: ENSG00000187775 | F24: HGNC:2946 | G24: Expert Review Green;Other | H24: Yes | I24: DNAH17 | J24: Ensembl ID | K24: Gold-standard | L24: Yes | M24: Male Infertility | N24: Motile Ciliopathies | O24: cilia | P24: Biallelic DNAH17 variants were reported in five men with isolated asthenozoospermia and sperm ODA loss, with loss of DNAH17 protein shown in two unrelated individuals (PMID 31178125). A homozygous missense variant cosegregated with asthenozoospermia in three brothers of a consanguineous family and was recapitulated in knock-in mice (PMID 31658987).
A25: DNAH5 | B25: Green | C25: BIALLELIC, autosomal or pseudoautosomal | D25: Ciliary dyskinesia, primary, 3, with or without situs inversus (MIM #608644) | E25: ENSG00000039139 | F25: HGNC:2950 | G25: Expert Review Green;Victorian Clinical Genetics Services | H25: Yes | I25: DNAH5 | J25: Ensembl ID | K25: Gold-standard | L25: Yes | M25: Mucociliary Clearance Disorder; Primary Ciliary Dyskinesia; Visceral Heterotaxy / Situs Inversus | N25: Motile Ciliopathies | O25: cilia
A26: DNAH7 | B26: Green | C26: BIALLELIC, autosomal or pseudoautosomal | D26: Primary ciliary dyskinesia, MONDO:0016575, DNAH7-related | E26: ENSG00000118997 | F26: HGNC:18661 | G26: Expert Review Green;Literature | H26: Yes | I26: DNAH7 | J26: Ensembl ID | K26: Gold-standard | L26: Yes | M26: Primary Ciliary Dyskinesia | N26: Motile Ciliopathies | O26: cilia; flagella
A27: DNAH9 | B27: Green | C27: BIALLELIC, autosomal or pseudoautosomal | D27: Ciliary dyskinesia, primary, 40, MIM# 618300 | E27: ENSG00000007174 | F27: HGNC:2953 | G27: Expert Review Green;Victorian Clinical Genetics Services | H27: Yes | I27: DNAH9 | J27: Ensembl ID | K27: Gold-standard | L27: Yes | M27: Primary Ciliary Dyskinesia | N27: Motile Ciliopathies | O27: cilia
A28: DNAI1 | B28: Green | C28: BIALLELIC, autosomal or pseudoautosomal | D28: Ciliary dyskinesia, primary, 1, with or without situs inversus, MIM# 244400 | E28: ENSG00000122735 | F28: HGNC:2954 | G28: Expert Review Green;Victorian Clinical Genetics Services | H28: Yes | I28: DNAI1 | J28: Ensembl ID | K28: Gold-standard | L28: Yes | M28: Primary Ciliary Dyskinesia; Visceral Heterotaxy / Situs Inversus | N28: Motile Ciliopathies | O28: cilia
A29: DNAI2 | B29: Green | C29: BIALLELIC, autosomal or pseudoautosomal | D29: Ciliary dyskinesia, primary, 9, with or without situs inversus, MIM# 612444 | E29: ENSG00000171595 | F29: HGNC:18744 | G29: Expert Review Green;Victorian Clinical Genetics Services | H29: Yes | I29: DNAI2 | J29: Ensembl ID | K29: Gold-standard | L29: Yes | M29: Primary Ciliary Dyskinesia | N29: Motile Ciliopathies | O29: cilia; flagella
A30: DNAJB13 | B30: Green | C30: BIALLELIC, autosomal or pseudoautosomal | D30: Ciliary dyskinesia, primary, 34 617091 | E30: ENSG00000187726 | F30: HGNC:30718 | G30: Expert Review Green;Literature | H30: Yes | I30: DNAJB13 | J30: Ensembl ID | K30: Gold-standard | L30: Yes | M30: Primary Ciliary Dyskinesia | N30: Motile Ciliopathies | O30: basal body; cilia
A31: DRC1 | B31: Green | C31: BIALLELIC, autosomal or pseudoautosomal | D31: Ciliary dyskinesia, primary, 21, MIM# 615294 | E31: ENSG00000157856 | F31: HGNC:24245 | G31: Expert Review Green;Victorian Clinical Genetics Services | H31: Yes | I31: DRC1 | J31: Ensembl ID | K31: Gold-standard | L31: Yes | M31: Male Infertility; Primary Ciliary Dyskinesia | N31: Motile Ciliopathies | O31: cilia
A32: DRC2 | B32: Green | C32: BIALLELIC, autosomal or pseudoautosomal | D32: Ciliary dyskinesia, primary, 27, MIM# 615504 | E32: ENSG00000139537 | F32: HGNC:29937 | G32: Expert Review Green;Victorian Clinical Genetics Services | H32: Yes | I32: DRC2 | J32: Ensembl ID | K32: Gold-standard | L32: Yes | M32: Primary Ciliary Dyskinesia | N32: Motile Ciliopathies | O32: basal body; cilia; transition zone
A33: DRC4 | B33: Green | C33: BIALLELIC, autosomal or pseudoautosomal | D33: Ciliary dyskinesia, primary, 33, mIM# 616726 | E33: ENSG00000141013 | F33: HGNC:4166 | G33: Expert Review Green;Victorian Clinical Genetics Services | H33: Yes | I33: DRC4 | J33: Ensembl ID | K33: Gold-standard | L33: Yes | M33: Primary Ciliary Dyskinesia | N33: Motile Ciliopathies | O33: cilia
A34: FOXJ1 | B34: Green | C34: MONOALLELIC, autosomal or pseudoautosomal, NOT imprinted | D34: Ciliary dyskinesia, primary, 43, MIM# 618699;hydrocephalus;chronic destructive airway disease;randomization of left/right body asymmetry | E34: ENSG00000129654 | F34: HGNC:3816 | G34: Expert Review Green;Literature | H34: Yes | I34: FOXJ1 | J34: Ensembl ID | K34: Cilia-associated | L34: Yes | M34: Hydrocephalus; Primary Ciliary Dyskinesia | N34: Primary Ciliopathies; Motile Ciliopathies | O34: cilia associated gene; nucleus
A35: GAS2L2 | B35: Green | C35: BIALLELIC, autosomal or pseudoautosomal | D35: Ciliary dyskinesia, primary, 41 (MIM # 618449) | E35: ENSG00000270765 | F35: HGNC:24846 | G35: Expert Review Green;Victorian Clinical Genetics Services | H35: Yes | I35: GAS2L2 | J35: Ensembl ID | K35: Gold-standard | L35: Yes | M35: Primary Ciliary Dyskinesia | N35: Motile Ciliopathies | O35: basal body; cilia; microtubules
A36: HYDIN | B36: Green | C36: BIALLELIC, autosomal or pseudoautosomal | D36: Ciliary dyskinesia, primary, 5 (MIM#608647) | E36: ENSG00000157423 | F36: HGNC:19368 | G36: Expert Review Green;Victorian Clinical Genetics Services | H36: Yes | I36: HYDIN | J36: Ensembl ID | K36: Gold-standard | L36: Yes | M36: Primary Ciliary Dyskinesia | N36: Motile Ciliopathies | O36: basal body
... A51: SPAG1 | B51: Green | C51: BIALLELIC, autosomal or pseudoautosomal | D51: Ciliary dyskinesia, primary, 28 (MIM#615505) | E51: ENSG00000104450 | F51: HGNC:11212 | G51: Expert Review Green;Victorian Clinical Genetics Services | H51: Yes | I51: SPAG1 | J51: Ensembl ID | K51: Gold-standard | L51: Yes | M51: Primary Ciliary Dyskinesia | N51: Motile Ciliopathies | O51: cilia; microtubules; nucleus
A52: TP73 | B52: Green | C52: BIALLELIC, autosomal or pseudoautosomal | D52: Ciliary dyskinesia, primary, 47, and lissencephaly, MIM#619466 | E52: ENSG00000078900 | F52: HGNC:12003 | G52: Expert Review Green;Literature | H52: Yes | I52: TP73 | J52: Ensembl ID | K52: Gold-standard | L52: Yes | M52: Mucociliary Clearance Disorder; Primary Ciliary Dyskinesia | N52: Motile Ciliopathies | O52: basal body; cilia; cytosol; nucleus | P52: Homozygous loss-of-function TP73 variants were found in seven individuals from five unrelated families with a mucociliary clearance disorder and lissencephaly, caused by defective multiciliated cell differentiation (Wallmeier et al. 2021, PMID 34077761).
A53: TTC12 | B53: Green | C53: BIALLELIC, autosomal or pseudoautosomal | D53: Ciliary dyskinesia | E53: ENSG00000149292 | F53: HGNC:23700 | G53: Expert Review Green;Literature | H53: Yes | I53: TTC12 | J53: Ensembl ID | K53: Gold-standard | L53: Yes | M53: Primary Ciliary Dyskinesia | N53: Motile Ciliopathies | O53: flagella
A54: TUBB4B | B54: Green | C54: MONOALLELIC, autosomal or pseudoautosomal, NOT imprinted | D54: Primary ciliary dyskinesia, MONDO:0016575, TUBB4B-related | E54: ENSG00000188229 | F54: HGNC:20771 | G54: Expert Review Green;Other | H54: Yes | I54: TUBB4B | J54: Ensembl ID | K54: Gold-standard | L54: Yes | M54: Leber Congenital Amaurosis; Primary Ciliary Dyskinesia | N54: Tissue-restricted Ciliopathies; Motile Ciliopathies | O54: basal body; cilia; cytosol; nucleus
...

Sheet Dilated Cardiomyopathy
A1: Gene symbol (panel) | B1: PanelApp rating | C1: Mode of inheritance | D1: Phenotypes (panel) | E1: Ensembl ID GRCh38 (panel) | F1: HGNC ID (panel) | G1: Panel sources | H1: In CiliaHub | I1: CiliaHub gene | J1: Match method | K1: CiliaHub category | L1: In ciliopathy module | M1: CiliaHub ciliopathies | N1: CiliaHub ciliopathy classification | O1: CiliaHub localization | P1: Note
A2: ACTC1 | B2: Green | C2: MONOALLELIC, autosomal or pseudoautosomal, NOT imprinted | D2: Cardiomyopathy, dilated, 1R, MIM# 613424 | E2: ENSG00000159251 | F2: HGNC:143 | G2: Expert Review Green;Victorian Clinical Genetics Services | H2: No | J2: Not found | K2: Not in CiliaHub | L2: No
A3: ACTN2 | B3: Green | C3: MONOALLELIC, autosomal or pseudoautosomal, imprinted status unknown | D3: Cardiomyopathy, dilated, 1AA, with or without LVNC, MIM# 612158;ACTN2-related cardiac and skeletal myopathy, MONDO:0700349 | E3: ENSG00000077522 | F3: HGNC:164 | G3: Expert Review;Expert Review Green | H3: Yes | I3: ACTN2 | J3: Ensembl ID | K3: Gold-standard | L3: No | O3: cilia; cytosol; transition zone
A4: ALMS1 | B4: Green | C4: BIALLELIC, autosomal or pseudoautosomal | D4: Cardiomyopathy, MONDO:0004994 | E4: ENSG00000116127 | F4: HGNC:428 | G4: Expert Review;Expert Review Green;NHS GMS | H4: Yes | I4: ALMS1 | J4: Ensembl ID | K4: Gold-standard | L4: Yes | M4: Alström Syndrome | N4: Primary Ciliopathies | O4: basal body; centrosome; cilia; cytosol
A5: ALPK3 | B5: Green | C5: BIALLELIC, autosomal or pseudoautosomal | D5: Cardiomyopathy, familial hypertrophic 27, MIM# 618052 | E5: ENSG00000136383 | F5: HGNC:17574 | G5: Expert Review Green;Victorian Clinical Genetics Services | H5: No | J5: Not found | K5: Not in CiliaHub | L5: No
A6: BAG3 | B6: Green | C6: MONOALLELIC, autosomal or pseudoautosomal, NOT imprinted | D6: Cardiomyopathy, dilated, 1HH, MIM# 613881;MONDO:0013479 | E6: ENSG00000151929 | F6: HGNC:939 | G6: Expert Review Green;Victorian Clinical Genetics Services | H6: Yes | I6: BAG3 | J6: Ensembl ID | K6: Gold-standard | L6: No | O6: basal body; cytosol; transition zone
A7: BAG5 | B7: Green | C7: BIALLELIC, autosomal or pseudoautosomal | D7: Cardiomyopathy, dilated, 2F, MIM# 619747 | E7: ENSG00000166170 | F7: HGNC:941 | G7: Expert Review Green;Literature | H7: No | J7: Not found | K7: Not in CiliaHub | L7: No
A8: C10orf71 | B8: Green | C8: MONOALLELIC, autosomal or pseudoautosomal, imprinted status unknown | D8: Cardiomyopathy, dilated, 1QQ, MIM# 621251 | E8: ENSG00000177354 | F8: HGNC:26973 | G8: Expert Review Green;Other | H8: No | J8: Not found | K8: Not in CiliaHub | L8: No
A9: CAP2 | B9: Green | C9: BIALLELIC, autosomal or pseudoautosomal | D9: Cardiomyopathy, dilated, 2I (MIM#620462) | E9: ENSG00000112186 | F9: HGNC:20039 | G9: Expert list;Expert Review Green | H9: No | J9: Not found | K9: Not in CiliaHub | L9: No
A10: DES | B10: Green | C10: MONOALLELIC, autosomal or pseudoautosomal, NOT imprinted | D10: Cardiomyopathy, dilated, 1I, MIM# 604765;MONDO:0011482 | E10: ENSG00000175084 | F10: HGNC:2770 | G10: ClinGen;Expert Review Green | H10: No | J10: Not found | K10: Not in CiliaHub | L10: No
A11: DMD | B11: Green | C11: X-LINKED: hemizygous mutation in males, monoallelic mutations in females may cause disease (may be less severe, later onset than males) | D11: Cardiomyopathy, dilated, 3B (MIM#302045) | E11: ENSG00000198947 | F11: HGNC:2928 | G11: Expert Review Green;Victorian Clinical Genetics Services | H11: No | J11: Not found | K11: Not in CiliaHub | L11: No
A12: DSP | B12: Green | C12: BOTH monoallelic and biallelic, autosomal or pseudoautosomal | D12: Dilated cardiomyopathy with woolly hair, keratoderma, and tooth agenesis, MIM# 615821;Cardiomyopathy, dilated, with woolly hair and keratoderma, MIM# 605676 | E12: ENSG00000096696 | F12: HGNC:3052 | G12: Expert Review Green;Victorian Clinical Genetics Services | H12: Yes | I12: DSP | J12: Ensembl ID via HGNC current symbol | K12: Gold-standard | L12: No | O12: basal body; Cell Junctions
A13: EMD | B13: Green | C13: X-LINKED: hemizygous mutation in males, biallelic mutations in females | D13: Emery-Dreifuss muscular dystrophy 1, X-linked MIM#310300 | E13: ENSG00000102119 | F13: HGNC:3331 | G13: Expert Review Green;Literature | H13: No | J13: Not found | K13: Not in CiliaHub | L13: No
A14: FKRP | B14: Green | C14: BIALLELIC, autosomal or pseudoautosomal | D14: Muscular dystrophy-dystroglycanopathy (limb-girdle), type C, 5, 607155 | E14: ENSG00000181027 | F14: HGNC:17997 | G14: Expert Review Green;Literature | H14: No | J14: Not found | K14: Not in CiliaHub | L14: No
A15: FLNC | B15: Green | C15: MONOALLELIC, autosomal or pseudoautosomal, imprinted status unknown | D15: Dilated cardiomyopathy | E15: ENSG00000128591 | F15: HGNC:3756 | G15: Expert Review Green;Literature | H15: No | J15: Not found | K15: Not in CiliaHub | L15: No
A16: JPH2 | B16: Green | C16: BOTH monoallelic and biallelic (but BIALLELIC mutations cause a more SEVERE disease form), autosomal or pseudoautosomal | D16: Cardiomyopathy, dilated, 2E, MIM# 619492 | E16: ENSG00000149596 | F16: HGNC:14202 | G16: Expert Review Green;Literature | H16: No | J16: Not found | K16: Not in CiliaHub | L16: No
A17: LAMP2 | B17: Green | C17: X-LINKED: hemizygous mutation in males, monoallelic mutations in females may cause disease (may be less severe, later onset than males) | D17: Danon disease, MIM#300257 | E17: ENSG00000005893 | F17: HGNC:6501 | G17: Expert Review Green;Victorian Clinical Genetics Services | H17: No | J17: Not found | K17: Not in CiliaHub | L17: No
A18: LMNA | B18: Green | C18: MONOALLELIC, autosomal or pseudoautosomal, NOT imprinted | D18: Cardiomyopathy, dilated, 1A, MIM# 115200 | E18: ENSG00000160789 | F18: HGNC:6636 | G18: Expert Review Green;Victorian Clinical Genetics Services | H18: No | J18: Not found | K18: Not in CiliaHub | L18: No
A19: MAP3K7 | B19: Green | C19: MONOALLELIC, autosomal or pseudoautosomal, NOT imprinted | D19: Dilated cardiomyopathy;Cardiospondylocarpofacial syndrome (CSCF) MIM# 157800 | E19: ENSG00000135341 | F19: HGNC:6859 | G19: Expert Review Green;Literature | H19: Yes | I19: MAP3K7 | J19: Ensembl ID | K19: Gold-standard | L19: No | O19: cilia; basal body
A20: MYH7 | B20: Green | C20: MONOALLELIC, autosomal or pseudoautosomal, NOT imprinted | D20: Cardiomyopathy, dilated, 1S, MIM# 613426;MONDO:0013262 | E20: ENSG00000092054 | F20: HGNC:7577 | G20: Expert Review Green;Victorian Clinical Genetics Services | H20: No | J20: Not found | K20: Not in CiliaHub | L20: No
A21: MYZAP | B21: Green | C21: BIALLELIC, autosomal or pseudoautosomal | D21: Cardiomyopathy, dilated, 2K, MIM# 620894 | E21: ENSG00000263155 | F21: HGNC:43444 | G21: Expert Review Green;Literature | H21: No | J21: Not found | K21: Not in CiliaHub | L21: No
A22: NEXN | B22: Green | C22: MONOALLELIC, autosomal or pseudoautosomal, NOT imprinted | D22: Cardiomyopathy, dilated, 1CC, MIM# 613122 | E22: ENSG00000162614 | F22: HGNC:29557 | G22: Expert Review Green;Victorian Clinical Genetics Services | H22: No | J22: Not found | K22: Not in CiliaHub | L22: No
A23: NKX2-5 | B23: Green | C23: MONOALLELIC, autosomal or pseudoautosomal, NOT imprinted | D23: Dilated cardiomyopathy | E23: ENSG00000183072 | F23: HGNC:2488 | G23: Expert list;Expert Review Green | H23: Yes | I23: NKX2-5 | J23: Ensembl ID | K23: Cilia-associated | L23: No | O23: cilia associated gene; nucleus
A24: PKP2 | B24: Green | C24: BIALLELIC, autosomal or pseudoautosomal | D24: Arrhythmogenic right ventricular dysplasia 9 (MIM#609040);Dilated cardiomyopathy, MONDO:0005021, PKP2-related;hypoplastic left heart syndrome;hydrops fetalis;ventricular septal defect;left ventricular non-compaction | E24: ENSG00000057294 | F24: HGNC:9024 | G24: Expert Review Green;Literature | H24: Yes | I24: PKP2 | J24: Ensembl ID via HGNC current symbol | K24: Gold-standard | L24: No | O24: basal body; Nucleoplasm; Cell Junctions
A25: PLN | B25: Green | C25: MONOALLELIC, autosomal or pseudoautosomal, NOT imprinted | D25: Cardiomyopathy, dilated, 1P, MIM# 609909 | E25: ENSG00000198523 | F25: HGNC:9080 | G25: Expert Review Green;Victorian Clinical Genetics Services | H25: No | J25: Not found | K25: Not in CiliaHub | L25: No
A26: PRDM16 | B26: Green | C26: MONOALLELIC, autosomal or pseudoautosomal, NOT imprinted | D26: Cardiomyopathy, dilated, 1LL MIM#615373;Left ventricular noncompaction 8 MIM#615373 | E26: ENSG00000142611 | F26: HGNC:14000 | G26: Expert Review Green;Literature | H26: No | J26: Not found | K26: Not in CiliaHub | L26: No
A27: RBM20 | B27: Green | C27: MONOALLELIC, autosomal or pseudoautosomal, NOT imprinted | D27: Cardiomyopathy, dilated, 1DD 613172 AD | E27: ENSG00000203867 | F27: HGNC:27424 | G27: Expert Review Green;Victorian Clinical Genetics Services | H27: No | J27: Not found | K27: Not in CiliaHub | L27: No
A28: SCN5A | B28: Green | C28: MONOALLELIC, autosomal or pseudoautosomal, NOT imprinted | D28: Cardiomyopathy, dilated, 1E, MIM# 601154;Multifocal ectopic Purkinje-related premature contractions (MEPPC) syndrome;SCN5A-related cardiac rhythm disorder MONDO:1010181 | E28: ENSG00000183873 | F28: HGNC:10593 | G28: Expert Review Green;Victorian Clinical Genetics Services | H28: No | J28: Not found | K28: Not in CiliaHub | L28: No
A29: TBX20 | B29: Green | C29: MONOALLELIC, autosomal or pseudoautosomal, NOT imprinted | D29: Dilated cardiomyopathy, MONDO:0005021, TBX20-related | E29: ENSG00000164532 | F29: HGNC:11598 | G29: Expert Review Green;Literature | H29: No | J29: Not found | K29: Not in CiliaHub | L29: No
A30: TBX5 | B30: Green | C30: MONOALLELIC, autosomal or pseudoautosomal, NOT imprinted | D30: Holt-Oram syndrome, MIM# 142900;Dilated cardiomyopathy | E30: ENSG00000089225 | F30: HGNC:11604 | G30: Expert Review Green;Literature | H30: No | J30: Not found | K30: Not in CiliaHub | L30: No
A31: TNNC1 | B31: Green | C31: MONOALLELIC, autosomal or pseudoautosomal, NOT imprinted | D31: Cardiomyopathy, dilated, 1Z, MIM# 611879;MONDO:0012745 | E31: ENSG00000114854 | F31: HGNC:11943 | G31: Expert Review Green;Victorian Clinical Genetics Services | H31: No | J31: Not found | K31: Not in CiliaHub | L31: No
A32: TNNI3 | B32: Green | C32: MONOALLELIC, autosomal or pseudoautosomal, NOT imprinted | D32: Cardiomyopathy, dilated, 1FF, MIM#613286 | E32: ENSG00000129991 | F32: HGNC:11947 | G32: Expert Review Green;Victorian Clinical Genetics Services | H32: No | J32: Not found | K32: Not in CiliaHub | L32: No
A33: TNNI3K | B33: Green | C33: MONOALLELIC, autosomal or pseudoautosomal, NOT imprinted | D33: Cardiac conduction disease with or without dilated cardiomyopathy, MIM# 616117 | E33: ENSG00000116783 | F33: HGNC:19661 | G33: Expert list;Expert Review Green | H33: No | J33: Not found | K33: Not in CiliaHub | L33: No
A34: TNNT2 | B34: Green | C34: MONOALLELIC, autosomal or pseudoautosomal, NOT imprinted | D34: Cardiomyopathy, dilated, 1D, MIM# 601494 | E34: ENSG00000118194 | F34: HGNC:11949 | G34: Expert Review Green;Victorian Clinical Genetics Services | H34: Yes | I34: TNNT2 | J34: Ensembl ID | K34: Cilia-associated | L34: No | O34: cilia associated gene; cytosol
A35: TPM1 | B35: Green | C35: MONOALLELIC, autosomal or pseudoautosomal, NOT imprinted | D35: Cardiomyopathy, dilated, 1Y, MIM# 611878 | E35: ENSG00000140416 | F35: HGNC:12010 | G35: Expert Review Green;Victorian Clinical Genetics Services | H35: No | J35: Not found | K35: Not in CiliaHub | L35: No
A36: TTN | B36: Green | C36: MONOALLELIC, autosomal or pseudoautosomal, NOT imprinted | D36: Cardiomyopathy, dilated, 1G, MIM#604145 | E36: ENSG00000155657 | F36: HGNC:12403 | G36: Expert Review Green;Victorian Clinical Genetics Services | H36: No | J36: Not found | K36: Not in CiliaHub | L36: No
A37: VCL | B37: Green | C37: MONOALLELIC, autosomal or pseudoautosomal, NOT imprinted | D37: Cardiomyopathy, dilated, 1W, MIM# 611407 | E37: ENSG00000035403 | F37: HGNC:12665 | G37: Expert Review Green;Victorian Clinical Genetics Services | H37: No | J37: Not found | K37: Not in CiliaHub | L37: No
A38: ABCC9 | B38: Amber | C38: MONOALLELIC, autosomal or pseudoautosomal, NOT imprinted | D38: dilated cardiomyopathy 1O MONDO:0012062 | E38: ENSG00000069431 | F38: HGNC:60 | G38: ClinGen;Expert Review Amber | H38: No | J38: Not found | K38: Not in CiliaHub | L38: No
A39: DOLK | B39: Amber | C39: BIALLELIC, autosomal or pseudoautosomal | D39: Congenital disorder of glycosylation, type Im MIM#610768 | E39: ENSG00000175283 | F39: HGNC:23406 | G39: Expert Review Amber;Literature | H39: No | J39: Not found | K39: Not in CiliaHub | L39: No
A40: DSG2 | B40: Amber | C40: BOTH monoallelic and biallelic, autosomal or pseudoautosomal | D40: Arrhythmogenic right ventricular dysplasia, 10, 610193;Cardiomyopathy, dilated, 1BB, 612877 | E40: ENSG00000046604 | F40: HGNC:3049 | G40: Expert Review Amber;Victorian Clinical Genetics Services | H40: No | J40: Not found | K40: Not in CiliaHub | L40: No
...
